Workbook

Sheet January Totals Madison
B1: Mon | C1: Tues | D1: Wed | E1: Thur | F1: Fri | G1: Sat | H1: Sun
A2: DATE | B2: 45663 | C2: 45664 | D2: 45665 | E2: 45666 | F2: 45667 | G2: 45668 | H2: 45669 | I2: Totals
A3: Med | B3: 79 | C3: 83 | D3: 92 | E3: 77 | F3: 89 | G3: 46 | H3: 0 | I3: =SUM(B3:H3) -> 466
A4: Chiro | B4: 45 | C4: 50 | D4: 47 | E4: 35 | F4: 49 | G4: 18 | H4: 0 | I4: =SUM(B4:H4) -> 244
A5: Pod | B5: 2 | C5: 12 | D5: 29 | E5: 2 | F5: 15 | G5: 0 | H5: 0 | I5: =SUM(B5:H5) -> 60
A6: PT | B6: 4 | C6: 3 | D6: 5 | E6: 0 | F6: 7 | G6: 0 | H6: 0 | I6: =SUM(B6:H6) -> 19
A7: MA | B7: 2 | C7: 1 | D7: 3 | E7: 3 | F7: 1 | G7: 0 | H7: 0 | I7: =SUM(B7:H7) -> 10
A8: IV | B8: 3 | C8: 0 | D8: 2 | E8: 1 | F8: 1 | G8: 0 | H8: 0 | I8: =SUM(B8:H8) -> 7
A9: TOTAL | B9: =SUM(B3:B8) -> 135 | C9: =SUM(C3:C8) -> 149 | D9: =SUM(D3:D8) -> 178 | E9: =SUM(E3:E8) -> 118 | F9: =SUM(F3:F8) -> 162 | G9: =SUM(G3:G8) -> 64 | H9: =SUM(H3:H8) -> 0 | I9: =SUM(B9:H9) -> 806
A10: Covid Test | B10: 0 | C10: 0 | D10: 0 | E10: 0 | F10: 0 | G10: 0 | H10: 0 | I10: =SUM(B10:H10) -> 0
A11: Telehealth | B11: 0 | C11: 0 | D11: 0 | E11: 0 | F11: 0 | G11: 0 | H11: 0 | I11: =SUM(B11:H11) -> 0
B14: Mon | C14: Tues | D14: Wed | E14: Thur | F14: Fri | G14: Sat | H14: Sun
A15: DATE | B15: 45670 | C15: 45671 | D15: 45672 | E15: 45673 | F15: 45674 | G15: 45675 | H15: 45676 | I15: Totals
A16: Med | B16: 82 | C16: 86 | D16: 97 | E16: 77 | F16: 99 | G16: 40 | H16: 0 | I16: =SUM(B16:H16) -> 481
A17: Chiro | B17: 48 | C17: 47 | D17: 54 | E17: 31 | F17: 45 | G17: 12 | H17: 0 | I17: =SUM(B17:H17) -> 237
A18: Pod | B18: 9 | C18: 6 | D18: 12 | E18: 0 | F18: 1 | G18: 0 | H18: 0 | I18: =SUM(B18:H18) -> 28
A19: PT | B19: 5 | C19: 6 | D19: 6 | E19: 0 | F19: 5 | G19: 0 | H19: 0 | I19: =SUM(B19:H19) -> 22
A20: MA | B20: 2 | C20: 3 | D20: 0 | E20: 1 | F20: 2 | G20: 0 | H20: 0 | I20: =SUM(B20:H20) -> 8
A21: IV | B21: 2 | C21: 1 | D21: 0 | E21: 1 | F21: 1 | G21: 1 | H21: 0 | I21: =SUM(B21:H21) -> 6
A22: TOTAL | B22: =SUM(B16:B21) -> 148 | C22: =SUM(C16:C21) -> 149 | D22: =SUM(D16:D21) -> 169 | E22: =SUM(E16:E21) -> 110 | F22: =SUM(F16:F21) -> 153 | G22: =SUM(G16:G21) -> 53 | H22: =SUM(H16:H21) -> 0 | I22: =SUM(B22:H22) -> 782
A23: Covid Test | C23: 0 | D23: 0 | E23: 0 | F23: 0 | G23: 0 | H23: 0 | I23: =SUM(B23:H23) -> 0
A24: Telehealth | C24: 0 | D24: 0 | E24: 0 | F24: 0 | G24: 0 | H24: 0 | I24: =SUM(B24:H24) -> 0
B27: Mon | C27: Tues | D27: Wed | E27: Thur | F27: Fri | G27: Sat | H27: Sun
A28: DATE | B28: 45677 | C28: 45678 | D28: 45679 | E28: 45680 | F28: 45681 | G28: 45682 | H28: 45683 | I28: Totals
A29: Med | B29: 86 | C29: 76 | D29: 87 | E29: 78 | F29: 84 | G29: 44 | H29: 0 | I29: =SUM(B29:H29) -> 455
A30: Chiro | B30: 39 | C30: 46 | D30: 49 | E30: 37 | F30: 52 | G30: 20 | H30: 0 | I30: =SUM(B30:H30) -> 243
A31: Pod | B31: 10 | C31: 11 | D31: 22 | E31: 1 | F31: 11 | G31: 0 | H31: 0 | I31: =SUM(B31:H31) -> 55
A32: PT | B32: 0 | C32: 6 | D32: 7 | E32: 0 | F32: 9 | G32: 0 | H32: 0 | I32: =SUM(B32:H32) -> 22
A33: MA | B33: 0 | C33: 2 | D33: 1 | E33: 2 | F33: 0 | G33: 0 | H33: 0 | I33: =SUM(B33:H33) -> 5
A34: IV | B34: 0 | C34: 0 | D34: 1 | E34: 2 | F34: 2 | G34: 0 | H34: 0 | I34: =SUM(B34:H34) -> 5
A35: TOTAL | B35: =SUM(B29:B34) -> 135 | C35: =SUM(C29:C34) -> 141 | D35: =SUM(D29:D34) -> 167 | E35: =SUM(E29:E34) -> 120 | F35: =SUM(F29:F34) -> 158 | G35: =SUM(G29:G34) -> 64 | H35: =SUM(H29:H34) -> 0 | I35: =SUM(B35:H35) -> 785
A36: Covid Test | B36: 0 | C36: 0 | D36: 0 | E36: 0 | F36: 0 | G36: 0 | H36: 0 | I36: =SUM(B36:H36) -> 0
A37: Telehealth | B37: 0 | C37: 0 | D37: 0 | E37: 0 | F37: 0 | G37: 0 | H37: 0 | I37: =SUM(B37:H37) -> 0
B40: Mon | C40: Tues | D40: Wed | E40: Thur | F40: Fri | G40: Sat | H40: Sun
A41: DATE | B41: 45684 | C41: 45685 | D41: 45686 | E41: 45687 | F41: 45688 | G41: 45689 | H41: 45690 | I41: Totals
A42: Med | B42: 78 | C42: 79 | D42: 86 | E42: 67 | F42: 89 | G42: 42 | H42: 0 | I42: =SUM(B42:H42) -> 441
A43: Chiro | B43: 52 | C43: 46 | D43: 51 | E43: 35 | F43: 56 | G43: 22 | H43: 0 | I43: =SUM(B43:H43) -> 262
A44: Pod | B44: 14 | C44: 5 | D44: 16 | E44: 1 | F44: 7 | G44: 0 | H44: 0 | I44: =SUM(B44:H44) -> 43
A45: PT | B45: 4 | C45: 6 | D45: 6 | E45: 0 | F45: 7 | G45: 0 | H45: 0 | I45: =SUM(B45:H45) -> 23
A46: MA | B46: 1 | C46: 2 | D46: 1 | E46: 1 | F46: 1 | G46: 0 | H46: 0 | I46: =SUM(B46:H46) -> 6
...

Sheet Janurary Provider Totals
B1: Mon | C1: Tues | D1: Wed | E1: Thur | F1: Fri | G1: Sat
A2: DATE | B2: 45663 | C2: 45664 | D2: 45665 | E2: 45666 | F2: 45667 | G2: 45668 | H2: Total
A3: Lisa | B3: 19 | C3: 25 | D3: 20 | E3: 20 | F3: 18 | G3: 46 | H3: =SUM(B3:G3) -> 148
A4: Bachman | B4: 27 | C4: 21 | D4: 30 | E4: 25 | F4: 26 | G4: 0 | H4: =SUM(B4:G4) -> 129
A5: Nicole | B5: 0 | C5: 0 | D5: 8 | E5: 0 | F5: 0 | G5: 0 | H5: =SUM(B5:G5) -> 8
A6: Nurse | B6: 33 | C6: 37 | D6: 34 | E6: 32 | F6: 45 | G6: 0 | H6: =SUM(B6:G6) -> 181
A7: TOTAL | B7: =SUM(B3:B6) -> 79 | C7: =SUM(C3:C6) -> 83 | D7: =SUM(D3:D6) -> 92 | E7: =SUM(E3:E6) -> 77 | F7: =SUM(F3:F6) -> 89 | G7: =SUM(G3:G6) -> 46 | H7: =SUM(B7:G7) -> 466
A8: Bachman 2 | H8: =SUM(B8:G8) -> 0
A9: Mac | H9: =SUM(B9:G9) -> 0
B10: Mon | C10: Tues | D10: Wed | E10: Thur | F10: Fri | G10: Sat
A11: DATE | B11: 45670 | C11: 45671 | D11: 45672 | E11: 45673 | F11: 45674 | G11: 45675 | H11: Total
A12: Lisa | B12: 23 | C12: 21 | D12: 20 | E12: 20 | F12: 26 | G12: 0 | H12: =SUM(B12:G12) -> 110
A13: Bachman | B13: 28 | C13: 29 | D13: 26 | E13: 25 | F13: 28 | G13: 40 | H13: =SUM(B13:G13) -> 176
A14: Nicole | B14: 0 | C14: 0 | D14: 9 | E14: 0 | F14: 0 | G14: 0 | H14: =SUM(B14:G14) -> 9
A15: Nurse | B15: 31 | C15: 36 | D15: 35 | E15: 32 | F15: 45 | G15: 0 | H15: =SUM(B15:G15) -> 179
A16: TOTAL | B16: =SUM(B12:B15) -> 82 | C16: =SUM(C12:C15) -> 86 | D16: =SUM(D12:D15) -> 90 | E16: =SUM(E12:E15) -> 77 | F16: =SUM(F12:F15) -> 99 | G16: =SUM(G12:G15) -> 40 | H16: =SUM(B16:G16) -> 474
A17: Leven | D17: 7 | H17: =SUM(B17:G17) -> 7
A18: Mac | H18: =SUM(B18:G18) -> 0
B19: Mon | C19: Tues | D19: Wed | E19: Thur | F19: Fri | G19: Sat
A20: DATE | B20: 45677 | C20: 45678 | D20: 45679 | E20: 45680 | F20: 45681 | G20: 45682 | H20: Total
A21: Lisa | B21: 23 | C21: 15 | D21: 17 | E21: 20 | F21: 20 | G21: 44 | H21: =SUM(B21:G21) -> 139
A22: Bachman | B22: 32 | C22: 19 | D22: 30 | E22: 20 | F22: 24 | G22: 0 | H22: =SUM(B22:G22) -> 125
A23: Fortunato | B23: 0 | C23: 0 | D23: 0 | E23: 0 | F23: 0 | G23: 0 | H23: =SUM(B23:G23) -> 0
A24: Nurse | B24: 31 | C24: 42 | D24: 40 | E24: 38 | F24: 40 | G24: 0 | H24: =SUM(B24:G24) -> 191
A25: TOTAL | B25: =SUM(B21:B24) -> 86 | C25: =SUM(C21:C24) -> 76 | D25: =SUM(D21:D24) -> 87 | E25: =SUM(E21:E24) -> 78 | F25: =SUM(F21:F24) -> 84 | G25: =SUM(G21:G24) -> 44 | H25: =SUM(B25:G25) -> 455
A26: Bachman 2 | H26: =SUM(B26:G26) -> 0
A27: Mac | H27: =SUM(B27:G27) -> 0
B28: Mon | C28: Tues | D28: Wed | E28: Thur | F28: Fri | G28: Sat
A29: DATE | B29: 45684 | C29: 45685 | D29: 45686 | E29: 45687 | F29: 45688 | G29: 45689 | H29: Total
A30: Lisa | B30: 17 | C30: 16 | D30: 21 | E30: 15 | F30: 20 | G30: 0 | H30: =SUM(B30:G30) -> 89
A31: Bachman | B31: 25 | C31: 23 | D31: 24 | E31: 20 | F31: 25 | G31: 42 | H31: =SUM(B31:G31) -> 159
A32: Fortunato | B32: 0 | C32: 0 | D32: 0 | E32: 0 | F32: 0 | G32: 0 | H32: =SUM(B32:G32) -> 0
A33: Nurse | B33: 36 | C33: 40 | D33: 41 | E33: 32 | F33: 44 | G33: 0 | H33: =SUM(B33:G33) -> 193
A34: TOTAL | B34: =SUM(B30:B33) -> 78 | C34: =SUM(C30:C33) -> 79 | D34: =SUM(D30:D33) -> 86 | E34: =SUM(E30:E33) -> 67 | F34: =SUM(F30:F33) -> 89 | G34: =SUM(G30:G33) -> 42 | H34: =SUM(B34:G34) -> 441
A35: Bachman 2 | H35: =SUM(B35:G35) -> 0
A36: Mac | H36: =SUM(B36:G36) -> 0
B37: Mon | C37: Tues | D37: Wed | E37: Thur | F37: Fri | G37: Sat
A38: DATE | H38: Total
A39: Lisa | B39: 0 | C39: 0 | D39: 0 | E39: 0 | F39: 0 | G39: 0 | H39: =SUM(B39:G39) -> 0
A40: Bachman | B40: 0 | C40: 0 | D40: 0 | E40: 0 | F40: 0 | G40: 0 | H40: =SUM(B40:G40) -> 0
...

Sheet February Totals Madison
B1: Mon | C1: Tues | D1: Wed | E1: Thur | F1: Fri | G1: Sat | H1: Sun
A2: DATE | B2: 45691 | C2: 45692 | D2: 45693 | E2: 45694 | F2: 45695 | G2: 45696 | H2: 45697 | I2: Totals
A3: Med | B3: 80 | C3: 89 | D3: 93 | E3: 79 | F3: 95 | G3: 40 | H3: 0 | I3: =SUM(B3:H3) -> 476
A4: Chiro | B4: 51 | C4: 49 | D4: 54 | E4: 33 | F4: 46 | G4: 26 | H4: 0 | I4: =SUM(B4:H4) -> 259
A5: Pod | B5: 8 | C5: 8 | D5: 12 | E5: 0 | F5: 8 | G5: 0 | H5: 0 | I5: =SUM(B5:H5) -> 36
A6: PT | B6: 3 | C6: 0 | D6: 2 | E6: 0 | F6: 6 | G6: 0 | H6: 0 | I6: =SUM(B6:H6) -> 11
A7: MA | B7: 1 | C7: 2 | D7: 0 | E7: 1 | F7: 0 | G7: 0 | H7: 0 | I7: =SUM(B7:H7) -> 4
A8: IV | B8: 2 | C8: 0 | D8: 0 | E8: 1 | F8: 0 | G8: 0 | H8: 0 | I8: =SUM(B8:H8) -> 3
A9: TOTAL | B9: =SUM(B3:B8) -> 145 | C9: =SUM(C3:C8) -> 148 | D9: =SUM(D3:D8) -> 161 | E9: =SUM(E3:E8) -> 114 | F9: =SUM(F3:F8) -> 155 | G9: =SUM(G3:G8) -> 66 | H9: =SUM(H3:H8) -> 0 | I9: =SUM(B9:H9) -> 789
A10: Leven | B10: 0 | C10: 0 | D10: 4 | E10: 0 | F10: 0 | G10: 0 | H10: 0 | I10: =SUM(B10:H10) -> 4
A11: Shadani | B11: 0 | C11: 0 | D11: 0 | E11: 6 | F11: 0 | G11: 0 | H11: 0 | I11: =SUM(B11:H11) -> 6
B14: Mon | C14: Tues | D14: Wed | E14: Thur | F14: Fri | G14: Sat | H14: Sun
A15: DATE | B15: 45698 | C15: 45699 | D15: 45700 | E15: 45701 | F15: 45702 | G15: 45703 | H15: 45704 | I15: Totals
A16: Med | B16: 76 | C16: 84 | D16: 92 | E16: 85 | F16: 79 | G16: 38 | H16: 0 | I16: =SUM(B16:H16) -> 454
A17: Chiro | B17: 38 | C17: 43 | D17: 57 | E17: 38 | F17: 44 | G17: 12 | H17: 0 | I17: =SUM(B17:H17) -> 232
A18: Pod | B18: 10 | C18: 6 | D18: 10 | E18: 1 | F18: 7 | G18: 0 | H18: 0 | I18: =SUM(B18:H18) -> 34
A19: PT | B19: 3 | C19: 6 | D19: 4 | E19: 0 | F19: 7 | G19: 0 | H19: 0 | I19: =SUM(B19:H19) -> 20
A20: MA | B20: 0 | C20: 1 | D20: 1 | E20: 0 | F20: 3 | G20: 1 | H20: 0 | I20: =SUM(B20:H20) -> 6
A21: IV | B21: 0 | C21: 1 | D21: 2 | E21: 1 | F21: 0 | G21: 0 | H21: 0 | I21: =SUM(B21:H21) -> 4
A22: TOTAL | B22: =SUM(B16:B21) -> 127 | C22: =SUM(C16:C21) -> 141 | D22: =SUM(D16:D21) -> 166 | E22: =SUM(E16:E21) -> 125 | F22: =SUM(F16:F21) -> 140 | G22: =SUM(G16:G21) -> 51 | H22: =SUM(H16:H21) -> 0 | I22: =SUM(B22:H22) -> 750
A23: Covid Test | C23: 0 | D23: 0 | E23: 0 | F23: 0 | G23: 0 | H23: 0 | I23: =SUM(B23:H23) -> 0
A24: Telehealth | C24: 0 | D24: 0 | E24: 0 | F24: 0 | G24: 0 | H24: 0 | I24: =SUM(B24:H24) -> 0
B27: Mon | C27: Tues | D27: Wed | E27: Thur | F27: Fri | G27: Sat | H27: Sun
A28: DATE | B28: 45705 | C28: 45706 | D28: 45707 | E28: 45708 | F28: 45709 | G28: 45710 | H28: 45711 | I28: Totals
A29: Med | B29: 79 | C29: 91 | D29: 101 | E29: 79 | F29: 82 | G29: 41 | H29: 0 | I29: =SUM(B29:H29) -> 473
A30: Chiro | B30: 68 | C30: 47 | D30: 65 | E30: 22 | F30: 46 | G30: 15 | H30: 0 | I30: =SUM(B30:H30) -> 263
A31: Pod | B31: 9 | C31: 9 | D31: 10 | E31: 0 | F31: 1 | H31: 0 | I31: =SUM(B31:H31) -> 29
A32: PT | B32: 3 | C32: 4 | D32: 7 | E32: 0 | F32: 5 | G32: 0 | H32: 0 | I32: =SUM(B32:H32) -> 19
A33: MA | B33: 1 | C33: 3 | D33: 2 | E33: 0 | F33: 2 | G33: 0 | H33: 0 | I33: =SUM(B33:H33) -> 8
A34: IV | B34: 2 | C34: 0 | D34: 3 | E34: 0 | F34: 1 | G34: 0 | H34: 0 | I34: =SUM(B34:H34) -> 6
A35: TOTAL | B35: =SUM(B29:B34) -> 162 | C35: =SUM(C29:C34) -> 154 | D35: =SUM(D29:D34) -> 188 | E35: =SUM(E29:E34) -> 101 | F35: =SUM(F29:F34) -> 137 | G35: =SUM(G29:G34) -> 56 | H35: =SUM(H29:H34) -> 0 | I35: =SUM(B35:H35) -> 798
A36: Covid Test | B36: 0 | C36: 0 | D36: 0 | E36: 0 | F36: 0 | G36: 0 | H36: 0 | I36: =SUM(B36:H36) -> 0
A37: Telehealth | B37: 0 | C37: 0 | D37: 0 | E37: 0 | F37: 0 | G37: 0 | H37: 0 | I37: =SUM(B37:H37) -> 0
B40: Mon | C40: Tues | D40: Wed | E40: Thur | F40: Fri | G40: Sat | H40: Sun
A41: DATE | B41: 45712 | C41: 45713 | D41: 45714 | E41: 45715 | F41: 45716 | G41: 45717 | H41: 45718 | I41: Totals
A42: Med | B42: 89 | C42: 87 | D42: 89 | E42: 87 | F42: 91 | G42: 40 | H42: 0 | I42: =SUM(B42:H42) -> 483
A43: Chiro | B43: 57 | C43: 42 | D43: 63 | E43: 36 | F43: 50 | G43: 23 | H43: 0 | I43: =SUM(B43:H43) -> 271
A44: Pod | B44: 16 | C44: 6 | D44: 10 | E44: 0 | F44: 14 | G44: 0 | H44: 0 | I44: =SUM(B44:H44) -> 46
A45: PT | B45: 4 | C45: 5 | D45: 6 | E45: 0 | F45: 6 | G45: 0 | H45: 0 | I45: =SUM(B45:H45) -> 21
A46: MA | B46: 1 | C46: 0 | D46: 1 | E46: 0 | F46: 1 | G46: 0 | H46: 0 | I46: =SUM(B46:H46) -> 3
...

Sheet February Provier Totals
B1: Mon | C1: Tues | D1: Wed | E1: Thur | F1: Fri | G1: Sat
A2: DATE | B2: 45327 | C2: 45328 | D2: 45329 | E2: 45330 | F2: 45331 | G2: 45332 | H2: Total
A3: Lisa | B3: 17 | C3: 25 | D3: 16 | E3: 25 | F3: 20 | G3: 40 | H3: =SUM(B3:G3) -> 143
A4: Bachman | B4: 30 | C4: 26 | D4: 27 | E4: 22 | F4: 27 | G4: 0 | H4: =SUM(B4:G4) -> 132
A5: Fortunato | B5: 0 | C5: 0 | D5: 0 | E5: 0 | F5: 0 | G5: 0 | H5: =SUM(B5:G5) -> 0
A6: Nurse | B6: 33 | C6: 38 | D6: 46 | E6: 32 | F6: 48 | G6: 0 | H6: =SUM(B6:G6) -> 197
A7: TOTAL | B7: =SUM(B3:B6) -> 80 | C7: =SUM(C3:C6) -> 89 | D7: =SUM(D3:D6) -> 89 | E7: =SUM(E3:E6) -> 79 | F7: =SUM(F3:F6) -> 95 | G7: =SUM(G3:G6) -> 40 | H7: =SUM(B7:G7) -> 472
A8: Bachman 2 | H8: =SUM(B8:G8) -> 0
A9: Mac | H9: =SUM(B9:G9) -> 0
B10: Mon | C10: Tues | D10: Wed | E10: Thur | F10: Fri | G10: Sat
A11: DATE | B11: 45334 | C11: 45335 | D11: 45336 | E11: 45337 | F11: 45338 | G11: 45339 | H11: Total
A12: Lisa | B12: 16 | C12: 21 | D12: 21 | E12: 23 | F12: 18 | G12: 0 | H12: =SUM(B12:G12) -> 99
A13: Bachman | B13: 25 | C13: 23 | D13: 29 | E13: 23 | F13: 21 | G13: 38 | H13: =SUM(B13:G13) -> 159
A14: Fortunato | B14: 0 | C14: 0 | D14: 0 | E14: 0 | F14: 0 | G14: 0 | H14: =SUM(B14:G14) -> 0
A15: Nurse | B15: 35 | C15: 40 | D15: 42 | E15: 39 | F15: 40 | G15: 0 | H15: =SUM(B15:G15) -> 196
A16: TOTAL | B16: =SUM(B12:B15) -> 76 | C16: =SUM(C12:C15) -> 84 | D16: =SUM(D12:D15) -> 92 | E16: =SUM(E12:E15) -> 85 | F16: =SUM(F12:F15) -> 79 | G16: =SUM(G12:G15) -> 38 | H16: =SUM(B16:G16) -> 454
A17: Bachman 2 | H17: =SUM(B17:G17) -> 0
A18: Mac | H18: =SUM(B18:G18) -> 0
B19: Mon | C19: Tues | D19: Wed | E19: Thur | F19: Fri | G19: Sat
A20: DATE | B20: 45341 | C20: 45342 | D20: 45343 | E20: 45344 | F20: 45345 | G20: 45346 | H20: Total
A21: Lisa | B21: 18 | C21: 22 | D21: 24 | E21: 20 | F21: 16 | G21: 41 | H21: =SUM(B21:G21) -> 141
A22: Bachman | B22: 27 | C22: 25 | D22: 34 | E22: 25 | F22: 27 | G22: 0 | H22: =SUM(B22:G22) -> 138
A23: Fortunato | B23: 0 | C23: 0 | D23: 0 | E23: 0 | F23: 0 | G23: 0 | H23: =SUM(B23:G23) -> 0
A24: Nurse | B24: 34 | C24: 44 | D24: 43 | E24: 34 | F24: 39 | G24: 0 | H24: =SUM(B24:G24) -> 194
A25: TOTAL | B25: =SUM(B21:B24) -> 79 | C25: =SUM(C21:C24) -> 91 | D25: =SUM(D21:D24) -> 101 | E25: =SUM(E21:E24) -> 79 | F25: =SUM(F21:F24) -> 82 | G25: =SUM(G21:G24) -> 41 | H25: =SUM(B25:G25) -> 473
A26: Bachman 2 | H26: =SUM(B26:G26) -> 0
A27: Mac | H27: =SUM(B27:G27) -> 0
B28: Mon | C28: Tues | D28: Wed | E28: Thur | F28: Fri | G28: Sat
A29: DATE | B29: 45348 | C29: 45349 | D29: 45350 | E29: 45351 | F29: 45352 | G29: 45353 | H29: Total
A30: Lisa | B30: 25 | C30: 22 | D30: 25 | E30: 22 | F30: 18 | G30: 0 | H30: =SUM(B30:G30) -> 112
A31: Bachman | B31: 25 | C31: 24 | D31: 26 | E31: 29 | F31: 32 | G31: 40 | H31: =SUM(B31:G31) -> 176
A32: Fortunato | B32: 0 | C32: 0 | D32: 0 | E32: 0 | F32: 0 | G32: 0 | H32: =SUM(B32:G32) -> 0
A33: Nurse | B33: 39 | C33: 41 | D33: 38 | E33: 36 | F33: 41 | G33: 0 | H33: =SUM(B33:G33) -> 195
A34: TOTAL | B34: =SUM(B30:B33) -> 89 | C34: =SUM(C30:C33) -> 87 | D34: =SUM(D30:D33) -> 89 | E34: =SUM(E30:E33) -> 87 | F34: =SUM(F30:F33) -> 91 | G34: =SUM(G30:G33) -> 40 | H34: =SUM(B34:G34) -> 483
A35: Bachman 2 | H35: =SUM(B35:G35) -> 0
A36: Mac | H36: =SUM(B36:G36) -> 0
B37: Mon | C37: Tues | D37: Wed | E37: Thur | F37: Fri | G37: Sat
A38: DATE | H38: Total
A39: Lisa | H39: =SUM(B39:G39) -> 0
A40: Bachman | H40: =SUM(B40:G40) -> 0
...

Sheet March Totals Madison
B1: Mon | C1: Tues | D1: Wed | E1: Thur | F1: Fri | G1: Sat | H1: Sun
A2: DATE | B2: 45719 | C2: 45720 | D2: 45721 | E2: 45722 | F2: 45723 | G2: 45724 | H2: 45725 | I2: Totals
A3: Med | B3: 85 | C3: 103 | D3: 86 | E3: 79 | F3: 82 | G3: 42 | H3: 0 | I3: =SUM(B3:H3) -> 477
A4: Chiro | B4: 57 | C4: 47 | D4: 55 | E4: 36 | F4: 55 | G4: 12 | H4: 0 | I4: =SUM(B4:H4) -> 262
A5: Pod | B5: 10 | C5: 5 | D5: 10 | E5: 0 | F5: 8 | G5: 0 | H5: 0 | I5: =SUM(B5:H5) -> 33
A6: PT | B6: 5 | C6: 7 | D6: 6 | E6: 0 | F6: 7 | G6: 0 | H6: 0 | I6: =SUM(B6:H6) -> 25
A7: MA | B7: 1 | C7: 2 | D7: 0 | E7: 0 | F7: 0 | G7: 0 | H7: 0 | I7: =SUM(B7:H7) -> 3
A8: IV | B8: 0 | C8: 1 | D8: 3 | E8: 0 | F8: 2 | G8: 0 | H8: 0 | I8: =SUM(B8:H8) -> 6
A9: TOTAL | B9: =SUM(B3:B8) -> 158 | C9: =SUM(C3:C8) -> 165 | D9: =SUM(D3:D8) -> 160 | E9: =SUM(E3:E8) -> 115 | F9: =SUM(F3:F8) -> 154 | G9: =SUM(G3:G8) -> 54 | H9: =SUM(H3:H8) -> 0 | I9: =SUM(B9:H9) -> 806
A10: Shadani | B10: 0 | C10: 0 | D10: 0 | E10: 5 | F10: 0 | G10: 0 | H10: 0 | I10: =SUM(B10:H10) -> 5
A11: Telehealth | B11: 0 | C11: 0 | D11: 0 | E11: 0 | F11: 0 | G11: 0 | H11: 0 | I11: =SUM(B11:H11) -> 0
B14: Mon | C14: Tues | D14: Wed | E14: Thur | F14: Fri | G14: Sat | H14: Sun
A15: DATE | B15: 45726 | C15: 45727 | D15: 45728 | E15: 45729 | F15: 45730 | G15: 45731 | H15: 45732 | I15: Totals
A16: Med | B16: 88 | C16: 92 | D16: 71 | E16: 76 | F16: 90 | G16: 40 | H16: 0 | I16: =SUM(B16:H16) -> 457
A17: Chiro | B17: 53 | C17: 49 | D17: 46 | E17: 42 | F17: 57 | G17: 23 | H17: 0 | I17: =SUM(B17:H17) -> 270
A18: Pod | B18: 0 | C18: 0 | D18: 7 | E18: 0 | F18: 2 | G18: 1 | H18: 0 | I18: =SUM(B18:H18) -> 10
A19: PT | B19: 6 | C19: 9 | D19: 7 | E19: 0 | F19: 10 | G19: 0 | H19: 0 | I19: =SUM(B19:H19) -> 32
A20: MA | B20: 1 | C20: 2 | D20: 1 | E20: 0 | F20: 1 | G20: 0 | H20: 0 | I20: =SUM(B20:H20) -> 5
A21: IV | B21: 0 | C21: 0 | D21: 1 | E21: 0 | F21: 1 | G21: 1 | H21: 0 | I21: =SUM(B21:H21) -> 3
A22: TOTAL | B22: =SUM(B16:B21) -> 148 | C22: =SUM(C16:C21) -> 152 | D22: =SUM(D16:D21) -> 133 | E22: =SUM(E16:E21) -> 118 | F22: =SUM(F16:F21) -> 161 | G22: =SUM(G16:G21) -> 65 | H22: =SUM(H16:H21) -> 0 | I22: =SUM(B22:H22) -> 777
A23: Covid Test | C23: 0 | D23: 0 | E23: 0 | F23: 0 | G23: 0 | H23: 0 | I23: =SUM(B23:H23) -> 0
A24: Telehealth | C24: 0 | D24: 0 | E24: 0 | F24: 0 | G24: 0 | H24: 0 | I24: =SUM(B24:H24) -> 0
B27: Mon | C27: Tues | D27: Wed | E27: Thur | F27: Fri | G27: Sat | H27: Sun
A28: DATE | B28: 45733 | C28: 45734 | D28: 45735 | E28: 45736 | F28: 45737 | G28: 45738 | H28: 45739 | I28: Totals
A29: Med | B29: 84 | C29: 106 | D29: 95 | E29: 80 | F29: 81 | G29: 46 | H29: 0 | I29: =SUM(B29:H29) -> 492
A30: Chiro | B30: 55 | C30: 46 | D30: 48 | E30: 39 | F30: 60 | G30: 13 | H30: 7 | I30: =SUM(B30:H30) -> 268
A31: Pod | B31: 26 | C31: 11 | D31: 19 | E31: 0 | F31: 13 | G31: 0 | H31: 0 | I31: =SUM(B31:H31) -> 69
A32: PT | B32: 6 | C32: 7 | D32: 5 | E32: 0 | F32: 9 | G32: 0 | H32: 0 | I32: =SUM(B32:H32) -> 27
A33: MA | B33: 0 | C33: 2 | D33: 0 | E33: 0 | F33: 1 | G33: 0 | H33: 0 | I33: =SUM(B33:H33) -> 3
A34: IV | B34: 0 | C34: 0 | D34: 0 | E34: 2 | F34: 2 | G34: 1 | H34: 0 | I34: =SUM(B34:H34) -> 5
A35: TOTAL | B35: =SUM(B29:B34) -> 171 | C35: =SUM(C29:C34) -> 172 | D35: =SUM(D29:D34) -> 167 | E35: =SUM(E29:E34) -> 121 | F35: =SUM(F29:F34) -> 166 | G35: =SUM(G29:G34) -> 60 | H35: =SUM(H29:H34) -> 7 | I35: =SUM(B35:H35) -> 864
A36: Covid Test | B36: 0 | C36: 0 | D36: 0 | E36: 0 | F36: 0 | G36: 0 | H36: 0 | I36: =SUM(B36:H36) -> 0
A37: Leven | B37: 0 | C37: 0 | D37: 4 | E37: 0 | F37: 0 | G37: 0 | H37: 0 | I37: =SUM(B37:H37) -> 4
B40: Mon | C40: Tues | D40: Wed | E40: Thur | F40: Fri | G40: Sat | H40: Sun
A41: DATE | B41: 45740 | C41: 45741 | D41: 45742 | E41: 45743 | F41: 45744 | G41: 45745 | H41: 45746 | I41: Totals
A42: Med | B42: 78 | C42: 91 | D42: 96 | E42: 76 | F42: 89 | G42: 45 | H42: 0 | I42: =SUM(B42:H42) -> 475
A43: Chiro | B43: 61 | C43: 44 | D43: 57 | E43: 42 | F43: 58 | G43: 21 | H43: 0 | I43: =SUM(B43:H43) -> 283
A44: Pod | B44: 14 | C44: 17 | D44: 20 | E44: 0 | F44: 11 | G44: 0 | H44: 0 | I44: =SUM(B44:H44) -> 62
A45: PT | B45: 7 | C45: 5 | D45: 5 | E45: 0 | F45: 9 | G45: 0 | H45: 0 | I45: =SUM(B45:H45) -> 26
A46: MA | B46: 1 | C46: 3 | D46: 1 | E46: 0 | F46: 1 | G46: 0 | H46: 0 | I46: =SUM(B46:H46) -> 6
...

Sheet March Provier Totals 
B1: Mon | C1: Tues | D1: Wed | E1: Thur | F1: Fri | G1: Sat
A2: DATE | B2: 45719 | C2: 45720 | D2: 45721 | E2: 45722 | F2: 45723 | G2: 45724 | H2: Total
A3: Lisa | B3: 17 | C3: 22 | D3: 21 | E3: 22 | F3: 21 | G3: 42 | H3: =SUM(B3:G3) -> 145
A4: Bachman | B4: 29 | C4: 29 | D4: 29 | E4: 23 | F4: 25 | G4: 0 | H4: =SUM(B4:G4) -> 135
A5: Fortunato | B5: 0 | C5: 0 | D5: 0 | E5: 0 | F5: 0 | G5: 0 | H5: =SUM(B5:G5) -> 0
A6: Nurse | B6: 39 | C6: 52 | D6: 36 | E6: 34 | F6: 36 | G6: 0 | H6: =SUM(B6:G6) -> 197
A7: TOTAL | B7: =SUM(B3:B6) -> 85 | C7: =SUM(C3:C6) -> 103 | D7: =SUM(D3:D6) -> 86 | E7: =SUM(E3:E6) -> 79 | F7: =SUM(F3:F6) -> 82 | G7: =SUM(G3:G6) -> 42 | H7: =SUM(B7:G7) -> 477
A8: Bachman 2 | H8: =SUM(B8:G8) -> 0
A9: Mac | H9: =SUM(B9:G9) -> 0
B10: Mon | C10: Tues | D10: Wed | E10: Thur | F10: Fri | G10: Sat
A11: DATE | B11: 45726 | C11: 45727 | D11: 45728 | E11: 45729 | F11: 45730 | G11: 45731 | H11: Total
A12: Lisa | B12: 22 | C12: 22 | D12: 0 | E12: 25 | F12: 24 | G12: 0 | H12: =SUM(B12:G12) -> 93
A13: Bachman | B13: 26 | C13: 25 | D13: 30 | E13: 23 | F13: 29 | G13: 40 | H13: =SUM(B13:G13) -> 173
A14: Fortunato | B14: 0 | C14: 0 | D14: 0 | E14: 0 | F14: 0 | G14: 0 | H14: =SUM(B14:G14) -> 0
A15: Nurse | B15: 40 | C15: 45 | D15: 41 | E15: 28 | F15: 37 | G15: 0 | H15: =SUM(B15:G15) -> 191
A16: TOTAL | B16: =SUM(B12:B15) -> 88 | C16: =SUM(C12:C15) -> 92 | D16: =SUM(D12:D15) -> 71 | E16: =SUM(E12:E15) -> 76 | F16: =SUM(F12:F15) -> 90 | G16: =SUM(G12:G15) -> 40 | H16: =SUM(B16:G16) -> 457
A17: Bachman 2 | H17: =SUM(B17:G17) -> 0
A18: Mac | H18: =SUM(B18:G18) -> 0
B19: Mon | C19: Tues | D19: Wed | E19: Thur | F19: Fri | G19: Sat
A20: DATE | B20: 45733 | C20: 45734 | D20: 45735 | E20: 45736 | F20: 45737 | G20: 45738 | H20: Total
A21: Lisa | B21: 19 | C21: 19 | D21: 22 | E21: 22 | F21: 21 | G21: 46 | H21: =SUM(B21:G21) -> 149
A22: Bachman | B22: 28 | C22: 39 | D22: 31 | E22: 25 | F22: 24 | G22: 0 | H22: =SUM(B22:G22) -> 147
A23: Fortunato | B23: 0 | C23: 0 | D23: 0 | E23: 0 | F23: 0 | G23: 0 | H23: =SUM(B23:G23) -> 0
A24: Nurse | B24: 37 | C24: 48 | D24: 38 | E24: 33 | F24: 36 | G24: 0 | H24: =SUM(B24:G24) -> 192
A25: TOTAL | B25: =SUM(B21:B24) -> 84 | C25: =SUM(C21:C24) -> 106 | D25: =SUM(D21:D24) -> 91 | E25: =SUM(E21:E24) -> 80 | F25: =SUM(F21:F24) -> 81 | G25: =SUM(G21:G24) -> 46 | H25: =SUM(B25:G25) -> 488
A26: Bachman 2 | H26: =SUM(B26:G26) -> 0
A27: Mac | H27: =SUM(B27:G27) -> 0
B28: Mon | C28: Tues | D28: Wed | E28: Thur | F28: Fri | G28: Sat
A29: DATE | B29: 45376 | C29: 45377 | D29: 45378 | E29: 45379 | F29: 45380 | G29: 45381 | H29: Total
A30: Lisa | B30: 21 | C30: 20 | D30: 21 | E30: 22 | F30: 20 | G30: 0 | H30: =SUM(B30:G30) -> 104
A31: Bachman | B31: 24 | C31: 29 | D31: 31 | E31: 20 | F31: 27 | G31: 45 | H31: =SUM(B31:G31) -> 176
A32: Fortunato | B32: 0 | C32: 0 | D32: 0 | E32: 0 | F32: 0 | G32: 0 | H32: =SUM(B32:G32) -> 0
A33: Nurse | B33: 33 | C33: 42 | D33: 44 | E33: 34 | F33: 42 | G33: 0 | H33: =SUM(B33:G33) -> 195
A34: TOTAL | B34: =SUM(B30:B33) -> 78 | C34: =SUM(C30:C33) -> 91 | D34: =SUM(D30:D33) -> 96 | E34: =SUM(E30:E33) -> 76 | F34: =SUM(F30:F33) -> 89 | G34: =SUM(G30:G33) -> 45 | H34: =SUM(B34:G34) -> 475
A35: Bachman 2 | H35: =SUM(B35:G35) -> 0
A36: Mac | H36: =SUM(B36:G36) -> 0
B37: Mon | C37: Tues | D37: Wed | E37: Thur | F37: Fri | G37: Sat
A38: DATE | H38: Total
A39: Lisa | H39: =SUM(B39:G39) -> 0
A40: Bachman | H40: =SUM(B40:G40) -> 0
...

Sheet April Totals Madison
B1: Mon | C1: Tues | D1: Wed | E1: Thur | F1: Fri | G1: Sat | H1: Sun
A2: DATE | B2: 45747 | C2: 45748 | D2: 45749 | E2: 45750 | F2: 45751 | G2: 45752 | H2: 45753 | I2: Totals
A3: Med | B3: 82 | C3: 95 | D3: 93 | E3: 98 | F3: 92 | G3: 43 | H3: 0 | I3: =SUM(B3:H3) -> 503
A4: Chiro | B4: 60 | C4: 52 | D4: 56 | E4: 38 | F4: 55 | G4: 18 | H4: 7 | I4: =SUM(B4:H4) -> 286
A5: Pod | B5: 11 | C5: 6 | D5: 16 | E5: 0 | F5: 6 | G5: 0 | H5: 0 | I5: =SUM(B5:H5) -> 39
A6: PT | B6: 7 | C6: 8 | D6: 6 | E6: 0 | F6: 8 | G6: 0 | H6: 0 | I6: =SUM(B6:H6) -> 29
A7: MA | B7: 3 | C7: 3 | D7: 0 | E7: 2 | F7: 0 | G7: 1 | H7: 0 | I7: =SUM(B7:H7) -> 9
A8: IV | B8: 3 | C8: 0 | D8: 1 | E8: 0 | F8: 3 | G8: 0 | H8: 0 | I8: =SUM(B8:H8) -> 7
A9: TOTAL | B9: =SUM(B3:B8) -> 166 | C9: =SUM(C3:C8) -> 164 | D9: =SUM(D3:D8) -> 172 | E9: =SUM(E3:E8) -> 138 | F9: =SUM(F3:F8) -> 164 | G9: =SUM(G3:G8) -> 62 | H9: =SUM(H3:H8) -> 7 | I9: =SUM(B9:H9) -> 873
A10: Leven | B10: 0 | C10: 0 | D10: 3 | E10: 0 | F10: 0 | G10: 0 | H10: 0 | I10: =SUM(B10:H10) -> 3
A11: Shadani | B11: 0 | C11: 0 | D11: 0 | E11: 2 | F11: 0 | G11: 0 | H11: 0 | I11: =SUM(B11:H11) -> 2
B14: Mon | C14: Tues | D14: Wed | E14: Thur | F14: Fri | G14: Sat | H14: Sun
A15: DATE | B15: 45754 | C15: 45755 | D15: 45756 | E15: 45757 | F15: 45758 | G15: 45759 | H15: 45760 | I15: Totals
A16: Med | B16: 94 | C16: 101 | D16: 84 | E16: 77 | F16: 89 | G16: 37 | H16: 0 | I16: =SUM(B16:H16) -> 482
A17: Chiro | B17: 55 | C17: 57 | D17: 61 | E17: 39 | F17: 59 | G17: 22 | H17: 0 | I17: =SUM(B17:H17) -> 293
A18: Pod | B18: 15 | C18: 18 | D18: 9 | E18: 0 | F18: 1 | G18: 0 | H18: 0 | I18: =SUM(B18:H18) -> 43
A19: PT | B19: 3 | C19: 5 | D19: 6 | E19: 0 | F19: 7 | G19: 0 | H19: 0 | I19: =SUM(B19:H19) -> 21
A20: MA | B20: 4 | C20: 1 | D20: 0 | E20: 1 | F20: 1 | G20: 0 | H20: 0 | I20: =SUM(B20:H20) -> 7
A21: IV | B21: 1 | C21: 1 | D21: 4 | E21: 0 | F21: 4 | G21: 0 | H21: 0 | I21: =SUM(B21:H21) -> 10
A22: TOTAL | B22: =SUM(B16:B21) -> 172 | C22: =SUM(C16:C21) -> 183 | D22: =SUM(D16:D21) -> 164 | E22: =SUM(E16:E21) -> 117 | F22: =SUM(F16:F21) -> 161 | G22: =SUM(G16:G21) -> 59 | H22: =SUM(H16:H21) -> 0 | I22: =SUM(B22:H22) -> 856
A23: Covid Test | C23: 0 | D23: 0 | E23: 0 | F23: 0 | G23: 0 | H23: 0 | I23: =SUM(B23:H23) -> 0
A24: Telehealth | C24: 0 | D24: 0 | E24: 0 | F24: 0 | G24: 0 | H24: 0 | I24: =SUM(B24:H24) -> 0
B27: Mon | C27: Tues | D27: Wed | E27: Thur | F27: Fri | G27: Sat | H27: Sun
A28: DATE | B28: 45761 | C28: 45762 | D28: 45763 | E28: 45764 | F28: 45765 | G28: 45766 | H28: 45767 | I28: Totals
A29: Med | B29: 76 | C29: 77 | D29: 73 | E29: 64 | F29: 81 | G29: 38 | H29: 0 | I29: =SUM(B29:H29) -> 409
A30: Chiro | B30: 60 | C30: 48 | D30: 48 | E30: 21 | F30: 52 | G30: 16 | H30: 0 | I30: =SUM(B30:H30) -> 245
A31: Pod | B31: 17 | C31: 13 | D31: 12 | E31: 1 | F31: 15 | G31: 0 | H31: 0 | I31: =SUM(B31:H31) -> 58
A32: PT | B32: 6 | C32: 7 | D32: 7 | E32: 0 | F32: 4 | G32: 0 | H32: 0 | I32: =SUM(B32:H32) -> 24
A33: MA | B33: 2 | C33: 2 | D33: 0 | E33: 0 | F33: 1 | G33: 0 | H33: 0 | I33: =SUM(B33:H33) -> 5
A34: IV | B34: 1 | C34: 0 | D34: 0 | E34: 0 | F34: 1 | G34: 0 | H34: 0 | I34: =SUM(B34:H34) -> 2
A35: TOTAL | B35: =SUM(B29:B34) -> 162 | C35: =SUM(C29:C34) -> 147 | D35: =SUM(D29:D34) -> 140 | E35: =SUM(E29:E34) -> 86 | F35: =SUM(F29:F34) -> 154 | G35: =SUM(G29:G34) -> 54 | H35: =SUM(H29:H34) -> 0 | I35: =SUM(B35:H35) -> 743
A36: Covid Test | B36: 0 | C36: 0 | D36: 0 | E36: 0 | F36: 0 | G36: 0 | H36: 0 | I36: =SUM(B36:H36) -> 0
A37: Telehealth | B37: 0 | C37: 0 | D37: 0 | E37: 0 | F37: 0 | G37: 0 | H37: 0 | I37: =SUM(B37:H37) -> 0
B40: Mon | C40: Tues | D40: Wed | E40: Thur | F40: Fri | G40: Sat | H40: Sun
A41: DATE | B41: 45768 | C41: 45769 | D41: 45770 | E41: 45771 | F41: 45772 | G41: 45773 | H41: 45774 | I41: Totals
A42: Med | B42: 95 | C42: 97 | D42: 95 | E42: 82 | F42: 81 | G42: 43 | H42: 0 | I42: =SUM(B42:H42) -> 493
A43: Chiro | B43: 67 | C43: 54 | D43: 61 | E43: 37 | F43: 54 | G43: 15 | H43: 0 | I43: =SUM(B43:H43) -> 288
A44: Pod | B44: 18 | C44: 9 | D44: 7 | E44: 2 | F44: 14 | G44: 0 | H44: 0 | I44: =SUM(B44:H44) -> 50
A45: PT | B45: 6 | C45: 4 | D45: 5 | E45: 0 | F45: 9 | G45: 0 | H45: 0 | I45: =SUM(B45:H45) -> 24
A46: MA | B46: 0 | C46: 0 | D46: 2 | E46: 1 | F46: 2 | G46: 0 | H46: 0 | I46: =SUM(B46:H46) -> 5
...

Sheet April Provier Totals 
B1: Mon | C1: Tues | D1: Wed | E1: Thur | F1: Fri | G1: Sat
A2: DATE | B2: 45747 | C2: 45748 | D2: 45749 | E2: 45750 | F2: 45751 | G2: 45752 | H2: Total
A3: Lisa | B3: 22 | C3: 20 | D3: 18 | E3: 23 | F3: 20 | G3: 43 | H3: =SUM(B3:G3) -> 146
A4: Bachman | B4: 28 | C4: 31 | D4: 28 | E4: 29 | F4: 32 | G4: 0 | H4: =SUM(B4:G4) -> 148
A5: Leven | B5: 0 | C5: 0 | D5: 4 | E5: 0 | F5: 0 | G5: 0 | H5: =SUM(B5:G5) -> 4
A6: Nurse | B6: 32 | C6: 44 | D6: 43 | E6: 39 | F6: 40 | G6: 0 | H6: =SUM(B6:G6) -> 198
A7: TOTAL | B7: =SUM(B3:B6) -> 82 | C7: =SUM(C3:C6) -> 95 | D7: =SUM(D3:D6) -> 93 | E7: =SUM(E3:E6) -> 91 | F7: =SUM(F3:F6) -> 92 | G7: =SUM(G3:G6) -> 43 | H7: =SUM(B7:G7) -> 496
A8: Shadani | E8: 3 | H8: =SUM(B8:G8) -> 3
A9: Mac | H9: =SUM(B9:G9) -> 0
B10: Mon | C10: Tues | D10: Wed | E10: Thur | F10: Fri | G10: Sat
A11: DATE | B11: 45754 | C11: 45755 | D11: 45756 | E11: 45757 | F11: 45758 | G11: 45759 | H11: Total
A12: Lisa | B12: 28 | C12: 22 | D12: 21 | E12: 21 | F12: 24 | G12: 0 | H12: =SUM(B12:G12) -> 116
A13: Bachman | B13: 31 | C13: 36 | D13: 24 | E13: 24 | F13: 29 | G13: 37 | H13: =SUM(B13:G13) -> 181
A14: Osman | B14: 4 | C14: 0 | D14: 0 | E14: 0 | F14: 0 | G14: 0 | H14: =SUM(B14:G14) -> 4
A15: Nurse | B15: 31 | C15: 43 | D15: 39 | E15: 32 | F15: 36 | G15: 0 | H15: =SUM(B15:G15) -> 181
A16: TOTAL | B16: =SUM(B12:B15) -> 94 | C16: =SUM(C12:C15) -> 101 | D16: =SUM(D12:D15) -> 84 | E16: =SUM(E12:E15) -> 77 | F16: =SUM(F12:F15) -> 89 | G16: =SUM(G12:G15) -> 37 | H16: =SUM(B16:G16) -> 482
A17: Bachman 2 | H17: =SUM(B17:G17) -> 0
A18: Mac | H18: =SUM(B18:G18) -> 0
B19: Mon | C19: Tues | D19: Wed | E19: Thur | F19: Fri | G19: Sat
A20: DATE | B20: 45761 | C20: 45762 | D20: 45763 | E20: 45764 | F20: 45765 | G20: 45766 | H20: Total
A21: Lisa | B21: 0 | C21: 0 | D21: 0 | E21: 0 | F21: 0 | G21: 38 | H21: =SUM(B21:G21) -> 38
A22: Bachman | B22: 39 | C22: 32 | D22: 31 | E22: 28 | F22: 38 | G22: 0 | H22: =SUM(B22:G22) -> 168
A23: Osman | B23: 3 | C23: 0 | D23: 0 | E23: 0 | F23: 0 | G23: 0 | H23: =SUM(B23:G23) -> 3
A24: Nurse | B24: 34 | C24: 45 | D24: 42 | E24: 36 | F24: 43 | G24: 0 | H24: =SUM(B24:G24) -> 200
A25: TOTAL | B25: =SUM(B21:B24) -> 76 | C25: =SUM(C21:C24) -> 77 | D25: =SUM(D21:D24) -> 73 | E25: =SUM(E21:E24) -> 64 | F25: =SUM(F21:F24) -> 81 | G25: =SUM(G21:G24) -> 38 | H25: =SUM(B25:G25) -> 409
A26: Bachman 2 | H26: =SUM(B26:G26) -> 0
A27: Mac | H27: =SUM(B27:G27) -> 0
B28: Mon | C28: Tues | D28: Wed | E28: Thur | F28: Fri | G28: Sat
A29: DATE | B29: 45768 | C29: 45769 | D29: 45770 | E29: 45771 | F29: 45772 | G29: 45773 | H29: Total
A30: Lisa | B30: 22 | C30: 20 | D30: 19 | E30: 17 | F30: 15 | G30: 0 | H30: =SUM(B30:G30) -> 93
A31: Bachman | B31: 34 | C31: 32 | D31: 37 | E31: 25 | F31: 25 | G31: 43 | H31: =SUM(B31:G31) -> 196
A32: Osman | B32: 4 | C32: 0 | D32: 0 | E32: 0 | F32: 0 | G32: 0 | H32: =SUM(B32:G32) -> 4
A33: Nurse | B33: 35 | C33: 45 | D33: 39 | E33: 40 | F33: 41 | G33: 0 | H33: =SUM(B33:G33) -> 200
A34: TOTAL | B34: =SUM(B30:B33) -> 95 | C34: =SUM(C30:C33) -> 97 | D34: =SUM(D30:D33) -> 95 | E34: =SUM(E30:E33) -> 82 | F34: =SUM(F30:F33) -> 81 | G34: =SUM(G30:G33) -> 43 | H34: =SUM(B34:G34) -> 493
A35: Bachman 2 | H35: =SUM(B35:G35) -> 0
A36: Mac | H36: =SUM(B36:G36) -> 0
B37: Mon | C37: Tues | D37: Wed | E37: Thur | F37: Fri | G37: Sat
A38: DATE | B38: 45775 | C38: 45776 | D38: 45777 | E38: 45778 | F38: 45779 | G38: 45780 | H38: Total
A39: Lisa | B39: 24 | C39: 19 | D39: 18 | E39: 17 | F39: 23 | G39: 40 | H39: =SUM(B39:G39) -> 141
A40: Bachman | B40: 28 | C40: 32 | D40: 31 | E40: 28 | F40: 33 | G40: 0 | H40: =SUM(B40:G40) -> 152
...

Sheet May Totals Madison
B1: Mon | C1: Tues | D1: Wed | E1: Thur | F1: Fri | G1: Sat | H1: Sun
A2: DATE | B2: 45782 | C2: 45783 | D2: 45784 | E2: 45785 | F2: 45786 | G2: 45787 | H2: 45788 | I2: Totals
A3: Med | B3: =SUM('May Provider Totals '!B7) -> 107 | C3: =SUM('May Provider Totals '!C7) -> 85 | D3: =SUM('May Provider Totals '!D7) -> 95 | E3: =SUM('May Provider Totals '!E7) -> 97 | F3: =SUM('May Provider Totals '!F7) -> 83 | G3: 39 | H3: 0 | I3: =SUM(B3:H3) -> 506
A4: Chiro | B4: 66 | C4: 54 | D4: 55 | E4: 46 | F4: 41 | G4: 20 | H4: 0 | I4: =SUM(B4:H4) -> 282
A5: Pod | B5: 9 | C5: 7 | D5: 13 | E5: 0 | F5: 3 | G5: 1 | H5: 0 | I5: =SUM(B5:H5) -> 33
A6: PT | B6: 7 | C6: 5 | D6: 5 | E6: 0 | F6: 11 | G6: 0 | H6: 0 | I6: =SUM(B6:H6) -> 28
A7: MA | B7: 1 | C7: 1 | D7: 2 | E7: 1 | F7: 2 | G7: 0 | H7: 0 | I7: =SUM(B7:H7) -> 7
A8: IV | B8: 1 | C8: 0 | D8: 3 | E8: 0 | F8: 2 | G8: 0 | H8: 0 | I8: =SUM(B8:H8) -> 6
A9: TOTAL | B9: =SUM(B3:B8) -> 191 | C9: =SUM(C3:C8) -> 152 | D9: =SUM(D3:D8) -> 173 | E9: =SUM(E3:E8) -> 144 | F9: =SUM(F3:F8) -> 142 | G9: =SUM(G3:G8) -> 60 | H9: =SUM(H3:H8) -> 0 | I9: =SUM(B9:H9) -> 862
A10: Covid Test | B10: 0 | C10: 0 | D10: 0 | E10: 0 | F10: 0 | G10: 0 | H10: 0 | I10: =SUM(B10:H10) -> 0
A11: Telehealth | B11: 0 | C11: 0 | D11: 0 | E11: 0 | F11: 0 | G11: 0 | H11: 0 | I11: =SUM(B11:H11) -> 0
B14: Mon | C14: Tues | D14: Wed | E14: Thur | F14: Fri | G14: Sat | H14: Sun
A15: DATE | B15: 45789 | C15: 45790 | D15: 45791 | E15: 45792 | F15: 45793 | G15: 45794 | H15: 45795 | I15: Totals
A16: Med | B16: 107 | C16: 97 | D16: 100 | E16: 92 | F16: 93 | G16: 36 | H16: 0 | I16: =SUM(B16:H16) -> 525
A17: Chiro | B17: 48 | C17: 58 | D17: 62 | E17: 44 | F17: 55 | G17: 18 | H17: 6 | I17: =SUM(B17:H17) -> 291
A18: Pod | B18: 11 | C18: 7 | D18: 14 | E18: 1 | F18: 0 | G18: 0 | H18: 0 | I18: =SUM(B18:H18) -> 33
A19: PT | B19: 5 | C19: 4 | D19: 8 | E19: 0 | F19: 6 | G19: 0 | H19: 0 | I19: =SUM(B19:H19) -> 23
A20: MA | B20: 2 | C20: 2 | D20: 2 | E20: 1 | F20: 1 | G20: 2 | H20: 0 | I20: =SUM(B20:H20) -> 10
A21: IV | B21: 3 | C21: 1 | D21: 2 | E21: 0 | F21: 2 | G21: 0 | H21: 0 | I21: =SUM(B21:H21) -> 8
A22: TOTAL | B22: =SUM(B16:B21) -> 176 | C22: =SUM(C16:C21) -> 169 | D22: =SUM(D16:D21) -> 188 | E22: =SUM(E16:E21) -> 138 | F22: =SUM(F16:F21) -> 157 | G22: =SUM(G16:G21) -> 56 | H22: =SUM(H16:H21) -> 6 | I22: =SUM(B22:H22) -> 890
A23: Covid Test | C23: 0 | D23: 0 | E23: 0 | F23: 0 | G23: 0 | H23: 0 | I23: =SUM(B23:H23) -> 0
A24: Telehealth | C24: 0 | D24: 0 | E24: 0 | F24: 0 | G24: 0 | H24: 0 | I24: =SUM(B24:H24) -> 0
B27: Mon | C27: Tues | D27: Wed | E27: Thur | F27: Fri | G27: Sat | H27: Sun
A28: DATE | B28: 45796 | C28: 45797 | D28: 45798 | E28: 45799 | F28: 45800 | G28: 45801 | H28: 45802 | I28: Totals
A29: Med | B29: 101 | C29: 103 | D29: 102 | E29: 88 | F29: 92 | G29: 33 | H29: 0 | I29: =SUM(B29:H29) -> 519
A30: Chiro | B30: 59 | C30: 54 | D30: 64 | E30: 40 | F30: 55 | G30: 9 | H30: 0 | I30: =SUM(B30:H30) -> 281
A31: Pod | B31: 14 | C31: 10 | D31: 16 | E31: 3 | F31: 0 | G31: 0 | H31: 0 | I31: =SUM(B31:H31) -> 43
A32: PT | B32: 5 | C32: 4 | D32: 7 | E32: 0 | F32: 10 | G32: 0 | H32: 0 | I32: =SUM(B32:H32) -> 26
A33: MA | B33: 0 | C33: 1 | D33: 0 | E33: 1 | F33: 2 | G33: 0 | H33: 0 | I33: =SUM(B33:H33) -> 4
A34: IV | B34: 0 | C34: 0 | D34: 3 | E34: 0 | F34: 2 | G34: 0 | H34: 0 | I34: =SUM(B34:H34) -> 5
A35: TOTAL | B35: =SUM(B29:B34) -> 179 | C35: =SUM(C29:C34) -> 172 | D35: =SUM(D29:D34) -> 192 | E35: =SUM(E29:E34) -> 132 | F35: =SUM(F29:F34) -> 161 | G35: =SUM(G29:G34) -> 42 | H35: =SUM(H29:H34) -> 0 | I35: =SUM(B35:H35) -> 878
A36: Covid Test | B36: 0 | C36: 0 | D36: 0 | E36: 0 | F36: 0 | G36: 0 | H36: 0 | I36: =SUM(B36:H36) -> 0
A37: Telehealth | B37: 0 | C37: 0 | D37: 0 | E37: 0 | F37: 0 | G37: 0 | H37: 0 | I37: =SUM(B37:H37) -> 0
B40: Mon | C40: Tues | D40: Wed | E40: Thur | F40: Fri | G40: Sat | H40: Sun
A41: DATE | B41: 45803 | C41: 45804 | D41: 45805 | E41: 45806 | F41: 45807 | G41: 45808 | H41: 45809 | I41: Totals
A42: Med | B42: 0 | C42: 123 | D42: 110 | E42: 85 | F42: 70 | G42: 40 | H42: 0 | I42: =SUM(B42:H42) -> 428
A43: Chiro | B43: 0 | C43: 64 | D43: 67 | E43: 42 | F43: 48 | G43: 15 | H43: 0 | I43: =SUM(B43:H43) -> 236
A44: Pod | B44: 0 | C44: 14 | D44: 16 | E44: 0 | F44: 9 | G44: 0 | H44: 0 | I44: =SUM(B44:H44) -> 39
A45: PT | B45: 0 | C45: 9 | D45: 7 | E45: 0 | F45: 9 | G45: 0 | H45: 0 | I45: =SUM(B45:H45) -> 25
A46: MA | B46: 0 | C46: 1 | D46: 0 | E46: 0 | F46: 4 | G46: 0 | H46: 0 | I46: =SUM(B46:H46) -> 5
...

Sheet May Provider Totals 
B1: Mon | C1: Tues | D1: Wed | E1: Thur | F1: Fri | G1: Sat
A2: DATE | B2: 45782 | C2: 45783 | D2: 45784 | E2: 45785 | F2: 45786 | G2: 45787 | H2: Total
A3: Lisa | B3: 27 | C3: 23 | D3: 19 | E3: 24 | F3: 18 | G3: 0 | H3: =SUM(B3:G3) -> 111
A4: Bachman | B4: 33 | C4: 28 | D4: 31 | E4: 30 | F4: 26 | G4: 39 | H4: =SUM(B4:G4) -> 187
A5: Osman | B5: 6 | C5: 0 | D5: 0 | E5: 0 | F5: 0 | G5: 0 | H5: =SUM(B5:G5) -> 6
A6: Nurse | B6: 41 | C6: 34 | D6: 45 | E6: 43 | F6: 39 | G6: 0 | H6: =SUM(B6:G6) -> 202
A7: TOTAL | B7: =SUM(B3:B6) -> 107 | C7: =SUM(C3:C6) -> 85 | D7: =SUM(D3:D6) -> 95 | E7: =SUM(E3:E6) -> 97 | F7: =SUM(F3:F6) -> 83 | G7: =SUM(G3:G6) -> 39 | H7: =SUM(B7:G7) -> 506
A8: Bachman 2 | H8: =SUM(B8:G8) -> 0
A9: Mac | H9: =SUM(B9:G9) -> 0
B10: Mon | C10: Tues | D10: Wed | E10: Thur | F10: Fri | G10: Sat
A11: DATE | B11: 45789 | C11: 45790 | D11: 45791 | E11: 45792 | F11: 45793 | G11: 45794 | H11: Total
A12: Lisa | B12: 19 | C12: 23 | D12: 20 | E12: 19 | F12: 23 | G12: 36 | H12: =SUM(B12:G12) -> 140
A13: Bachman | B13: 31 | C13: 29 | D13: 34 | E13: 26 | F13: 25 | G13: 0 | H13: =SUM(B13:G13) -> 145
A14: Osman | B14: 17 | C14: 0 | D14: 0 | E14: 0 | F14: 0 | G14: 0 | H14: =SUM(B14:G14) -> 17
A15: Nurse | B15: 40 | C15: 45 | D15: 46 | E15: 47 | F15: 45 | G15: 0 | H15: =SUM(B15:G15) -> 223
A16: TOTAL | B16: =SUM(B12:B15) -> 107 | C16: =SUM(C12:C15) -> 97 | D16: =SUM(D12:D15) -> 100 | E16: =SUM(E12:E15) -> 92 | F16: =SUM(F12:F15) -> 93 | G16: =SUM(G12:G15) -> 36 | H16: =SUM(B16:G16) -> 525
A17: Bachman 2 | H17: =SUM(B17:G17) -> 0
A18: Mac | H18: =SUM(B18:G18) -> 0
B19: Mon | C19: Tues | D19: Wed | E19: Thur | F19: Fri | G19: Sat
A20: DATE | B20: 45796 | C20: 45797 | D20: 45798 | E20: 45799 | F20: 45800 | G20: 45801 | H20: Total
A21: Lisa | B21: 23 | C21: 25 | D21: 23 | E21: 23 | F21: 20 | G21: 0 | H21: =SUM(B21:G21) -> 114
A22: Bachman | B22: 23 | C22: 29 | D22: 27 | E22: 24 | F22: 25 | G22: 33 | H22: =SUM(B22:G22) -> 161
A23: Osman | B23: 11 | C23: 0 | D23: 0 | E23: 0 | F23: 0 | G23: 0 | H23: =SUM(B23:G23) -> 11
A24: Nurse | B24: 44 | C24: 49 | D24: 48 | E24: 41 | F24: 47 | G24: 0 | H24: =SUM(B24:G24) -> 229
A25: TOTAL | B25: =SUM(B21:B24) -> 101 | C25: =SUM(C21:C24) -> 103 | D25: =SUM(D21:D24) -> 98 | E25: =SUM(E21:E24) -> 88 | F25: =SUM(F21:F24) -> 92 | G25: =SUM(G21:G24) -> 33 | H25: =SUM(B25:G25) -> 515
A26: Leven | D26: 4 | H26: =SUM(B26:G26) -> 4
A27: Mac | H27: =SUM(B27:G27) -> 0
B28: Mon | C28: Tues | D28: Wed | E28: Thur | F28: Fri | G28: Sat
A29: DATE | B29: 45803 | C29: 45804 | D29: 45805 | E29: 45806 | F29: 45807 | G29: 45808 | H29: Total
A30: Lisa | B30: 0 | C30: 17 | D30: 21 | E30: 20 | F30: 14 | G30: 35 | H30: =SUM(B30:G30) -> 107
A31: Bachman | B31: 0 | C31: 29 | D31: 27 | E31: 25 | F31: 20 | G31: 0 | H31: =SUM(B31:G31) -> 101
A32: Osman | B32: 0 | C32: 4 | D32: 0 | E32: 0 | F32: 0 | G32: 5 | H32: =SUM(B32:G32) -> 9
A33: Nurse | B33: 0 | C33: 73 | D33: 62 | E33: 40 | F33: 36 | G33: 0 | H33: =SUM(B33:G33) -> 211
A34: TOTAL | B34: =SUM(B30:B33) -> 0 | C34: =SUM(C30:C33) -> 123 | D34: =SUM(D30:D33) -> 110 | E34: =SUM(E30:E33) -> 85 | F34: =SUM(F30:F33) -> 70 | G34: =SUM(G30:G33) -> 40 | H34: =SUM(B34:G34) -> 428
A35: Bachman 2 | H35: =SUM(B35:G35) -> 0
A36: Mac | H36: =SUM(B36:G36) -> 0
B37: Mon | C37: Tues | D37: Wed | E37: Thur | F37: Fri | G37: Sat
A38: DATE | H38: Total
A39: Lisa | H39: =SUM(B39:G39) -> 0
A40: Bachman | H40: =SUM(B40:G40) -> 0
...

Sheet June Totals Madison
B1: Mon | C1: Tues | D1: Wed | E1: Thur | F1: Fri | G1: Sat | H1: Sun
A2: DATE | B2: 45810 | C2: 45811 | D2: 45812 | E2: 45813 | F2: 45814 | G2: 45815 | H2: 45816 | I2: Totals
A3: Med | B3: =SUM('June Provier Totals '!B7) -> 82 | C3: =SUM('June Provier Totals '!C7) -> 100 | D3: 101 | E3: 92 | F3: =SUM('June Provier Totals '!F7) -> 92 | G3: 35 | H3: 0 | I3: =SUM(B3:H3) -> 502
A4: Chiro | B4: 59 | C4: 57 | D4: 57 | E4: 42 | F4: 55 | G4: 18 | H4: 0 | I4: =SUM(B4:H4) -> 288
A5: Pod | B5: 14 | C5: 8 | D5: 2 | E5: 4 | F5: 0 | G5: 0 | H5: 0 | I5: =SUM(B5:H5) -> 28
A6: PT | B6: 4 | C6: 6 | D6: 6 | E6: 0 | F6: 8 | G6: 0 | H6: 0 | I6: =SUM(B6:H6) -> 24
A7: MA | B7: 0 | C7: 1 | D7: 2 | E7: 1 | F7: 1 | G7: 0 | H7: 0 | I7: =SUM(B7:H7) -> 5
A8: IV | B8: 4 | C8: 0 | D8: 3 | E8: 1 | F8: 2 | G8: 0 | H8: 0 | I8: =SUM(B8:H8) -> 10
A9: TOTAL | B9: =SUM(B3:B8) -> 163 | C9: =SUM(C3:C8) -> 172 | D9: =SUM(D3:D8) -> 171 | E9: =SUM(E3:E8) -> 140 | F9: =SUM(F3:F8) -> 158 | G9: =SUM(G3:G8) -> 53 | H9: =SUM(H3:H8) -> 0 | I9: =SUM(B9:H9) -> 857
A10: Leven | B10: 0 | C10: 0 | D10: 2 | E10: 0 | F10: 0 | G10: 0 | H10: 0 | I10: =SUM(B10:H10) -> 2
A11: Telehealth | B11: 0 | C11: 0 | D11: 0 | E11: 5 | F11: 0 | G11: 0 | H11: 0 | I11: =SUM(B11:H11) -> 5
B14: Mon | C14: Tues | D14: Wed | E14: Thur | F14: Fri | G14: Sat | H14: Sun
A15: DATE | B15: 45817 | C15: 45818 | D15: 45819 | E15: 45820 | F15: 45821 | G15: 45822 | H15: 45823 | I15: Totals
A16: Med | B16: 104 | C16: 104 | D16: 100 | E16: 88 | F16: 88 | G16: 38 | H16: 0 | I16: =SUM(B16:H16) -> 522
A17: Chiro | B17: 59 | C17: 59 | D17: 46 | E17: 38 | F17: 53 | G17: 14 | H17: 0 | I17: =SUM(B17:H17) -> 269
A18: Pod | B18: 13 | C18: 11 | D18: 4 | E18: 0 | F18: 12 | G18: 1 | H18: 0 | I18: =SUM(B18:H18) -> 41
A19: PT | B19: 4 | C19: 9 | D19: 4 | E19: 0 | F19: 7 | G19: 0 | H19: 0 | I19: =SUM(B19:H19) -> 24
A20: MA | B20: 3 | C20: 3 | D20: 1 | E20: 1 | F20: 1 | G20: 1 | H20: 0 | I20: =SUM(B20:H20) -> 10
A21: IV | B21: 3 | C21: 0 | D21: 0 | E21: 0 | F21: 1 | G21: 0 | H21: 0 | I21: =SUM(B21:H21) -> 4
A22: TOTAL | B22: =SUM(B16:B21) -> 186 | C22: =SUM(C16:C21) -> 186 | D22: =SUM(D16:D21) -> 155 | E22: =SUM(E16:E21) -> 127 | F22: =SUM(F16:F21) -> 162 | G22: =SUM(G16:G21) -> 54 | H22: =SUM(H16:H21) -> 0 | I22: =SUM(B22:H22) -> 870
A23: Covid Test | C23: 0 | D23: 0 | E23: 0 | F23: 0 | G23: 0 | H23: 0 | I23: =SUM(B23:H23) -> 0
A24: Telehealth | C24: 0 | D24: 0 | E24: 0 | F24: 0 | G24: 0 | H24: 0 | I24: =SUM(B24:H24) -> 0
B27: Mon | C27: Tues | D27: Wed | E27: Thur | F27: Fri | G27: Sat | H27: Sun
A28: DATE | B28: 45824 | C28: 45825 | D28: 45826 | E28: 45827 | F28: 45828 | G28: 45829 | H28: 45830 | I28: Totals
A29: Med | B29: 91 | C29: 105 | D29: 103 | E29: 88 | F29: 78 | G29: 44 | H29: 0 | I29: =SUM(B29:H29) -> 509
A30: Chiro | B30: 46 | C30: 57 | D30: 62 | E30: 52 | F30: 49 | G30: 13 | H30: 0 | I30: =SUM(B30:H30) -> 279
A31: Pod | B31: 9 | C31: 11 | D31: 19 | E31: 1 | F31: 1 | G31: 0 | H31: 0 | I31: =SUM(B31:H31) -> 41
A32: PT | B32: 5 | C32: 5 | D32: 6 | E32: 0 | F32: 5 | G32: 0 | H32: 0 | I32: =SUM(B32:H32) -> 21
A33: MA | B33: 3 | C33: 0 | D33: 0 | E33: 0 | F33: 0 | G33: 0 | H33: 0 | I33: =SUM(B33:H33) -> 3
A34: IV | B34: 1 | C34: 0 | D34: 2 | E34: 0 | F34: 3 | G34: 1 | H34: 0 | I34: =SUM(B34:H34) -> 7
A35: TOTAL | B35: =SUM(B29:B34) -> 155 | C35: =SUM(C29:C34) -> 178 | D35: =SUM(D29:D34) -> 192 | E35: =SUM(E29:E34) -> 141 | F35: =SUM(F29:F34) -> 136 | G35: =SUM(G29:G34) -> 58 | H35: =SUM(H29:H34) -> 0 | I35: =SUM(B35:H35) -> 860
A36: Covid Test | B36: 0 | C36: 0 | D36: 0 | E36: 0 | F36: 0 | G36: 0 | H36: 0 | I36: =SUM(B36:H36) -> 0
A37: Telehealth | B37: 0 | C37: 0 | D37: 0 | E37: 0 | F37: 0 | G37: 0 | H37: 0 | I37: =SUM(B37:H37) -> 0
B40: Mon | C40: Tues | D40: Wed | E40: Thur | F40: Fri | G40: Sat | H40: Sun
A41: DATE | B41: 45831 | C41: 45832 | D41: 45833 | E41: 45834 | F41: 45835 | G41: 45836 | H41: 45837 | I41: Totals
A42: Med | B42: 103 | C42: 114 | D42: 93 | E42: 81 | F42: 102 | G42: 36 | H42: 0 | I42: =SUM(B42:H42) -> 529
A43: Chiro | B43: 54 | C43: 49 | D43: 55 | E43: 40 | F43: 60 | G43: 18 | H43: 0 | I43: =SUM(B43:H43) -> 276
A44: Pod | B44: 14 | C44: 4 | D44: 11 | E44: 2 | F44: 0 | G44: 0 | H44: 0 | I44: =SUM(B44:H44) -> 31
A45: PT | B45: 5 | C45: 5 | D45: 6 | E45: 0 | F45: 8 | G45: 0 | H45: 0 | I45: =SUM(B45:H45) -> 24
A46: MA | B46: 4 | C46: 0 | D46: 0 | E46: 0 | F46: 0 | G46: 0 | H46: 0 | I46: =SUM(B46:H46) -> 4
...

Sheet June Provier Totals 
B1: Mon | C1: Tues | D1: Wed | E1: Thur | F1: Fri | G1: Sat
A2: DATE | B2: 45810 | C2: 45811 | D2: 45812 | E2: 45813 | F2: 45814 | G2: 45815 | H2: Total
A3: Lisa | B3: 15 | C3: 22 | D3: 25 | E3: 22 | F3: 18 | G3: 0 | H3: =SUM(B3:G3) -> 102
A4: Bachman | B4: 31 | C4: 23 | D4: 33 | E4: 24 | F4: 34 | G4: 35 | H4: =SUM(B4:G4) -> 180
A5: Osman | B5: 0 | C5: 0 | D5: 0 | E5: 0 | F5: 0 | G5: 0 | H5: =SUM(B5:G5) -> 0
A6: Nurse | B6: 36 | C6: 55 | D6: 41 | E6: 41 | F6: 40 | G6: 0 | H6: =SUM(B6:G6) -> 213
A7: TOTAL | B7: =SUM(B3:B6) -> 82 | C7: =SUM(C3:C6) -> 100 | D7: =SUM(D3:D6) -> 99 | E7: =SUM(E3:E6) -> 87 | F7: =SUM(F3:F6) -> 92 | G7: =SUM(G3:G6) -> 35 | H7: =SUM(B7:G7) -> 495
A8: Leven | D8: 2 | H8: =SUM(B8:G8) -> 2
A9: Shadani | E9: 5 | H9: =SUM(B9:G9) -> 5
B10: Mon | C10: Tues | D10: Wed | E10: Thur | F10: Fri | G10: Sat
A11: DATE | B11: 45817 | C11: 45818 | D11: 45819 | E11: 45820 | F11: 45821 | G11: 45822 | H11: Total
A12: Lisa | B12: 22 | C12: 24 | D12: 24 | E12: 23 | F12: 21 | G12: 20 | H12: =SUM(B12:G12) -> 134
A13: Bachman | B13: 31 | C13: 29 | D13: 33 | E13: 24 | F13: 32 | G13: 0 | H13: =SUM(B13:G13) -> 149
A14: osman | B14: 16 | C14: 0 | D14: 0 | E14: 0 | F14: 0 | G14: 0 | H14: =SUM(B14:G14) -> 16
A15: Nurse | B15: 35 | C15: 51 | D15: 43 | E15: 41 | F15: 35 | G15: 18 | H15: =SUM(B15:G15) -> 223
A16: TOTAL | B16: =SUM(B12:B15) -> 104 | C16: =SUM(C12:C15) -> 104 | D16: =SUM(D12:D15) -> 100 | E16: =SUM(E12:E15) -> 88 | F16: =SUM(F12:F15) -> 88 | G16: =SUM(G12:G15) -> 38 | H16: =SUM(B16:G16) -> 522
A17: Bachman 2 | H17: =SUM(B17:G17) -> 0
A18: Mac | H18: =SUM(B18:G18) -> 0
B19: Mon | C19: Tues | D19: Wed | E19: Thur | F19: Fri | G19: Sat
A20: DATE | B20: 45824 | C20: 45825 | D20: 45826 | E20: 45827 | F20: 45828 | G20: 45829 | H20: Total
A21: Lisa | B21: 19 | C21: 25 | D21: 23 | E21: 27 | F21: 19 | G21: 0 | H21: =SUM(B21:G21) -> 113
A22: Bachman | B22: 23 | C22: 28 | D22: 32 | E22: 21 | F22: 23 | G22: 21 | H22: =SUM(B22:G22) -> 148
A23: Osman | B23: 9 | C23: 0 | D23: 0 | E23: 0 | F23: 0 | G23: 2 | H23: =SUM(B23:G23) -> 11
A24: Nurse | B24: 40 | C24: 52 | D24: 48 | E24: 40 | F24: 36 | G24: 21 | H24: =SUM(B24:G24) -> 237
A25: TOTAL | B25: =SUM(B21:B24) -> 91 | C25: =SUM(C21:C24) -> 105 | D25: =SUM(D21:D24) -> 103 | E25: =SUM(E21:E24) -> 88 | F25: =SUM(F21:F24) -> 78 | G25: =SUM(G21:G24) -> 44 | H25: =SUM(B25:G25) -> 509
A26: Bachman 2 | B26: 9 | C26: 4 | D26: 21 | E26: 0 | F26: 1 | H26: =SUM(B26:G26) -> 35
A27: Mac | H27: =SUM(B27:G27) -> 0
B28: Mon | C28: Tues | D28: Wed | E28: Thur | F28: Fri | G28: Sat
A29: DATE | B29: 45831 | C29: 45832 | D29: 45833 | E29: 45834 | F29: 45835 | G29: 45836 | H29: Total
A30: Lisa | B30: 21 | C30: 20 | D30: 0 | E30: 21 | F30: 28 | G30: 17 | H30: =SUM(B30:G30) -> 107
A31: Bachman | B31: 28 | C31: 34 | D31: 39 | E31: 17 | F31: 28 | G31: 0 | H31: =SUM(B31:G31) -> 146
A32: Osman | B32: 14 | C32: 0 | D32: 0 | E32: 0 | F32: 0 | G32: 0 | H32: =SUM(B32:G32) -> 14
A33: Nurse | B33: 40 | C33: 60 | D33: 54 | E33: 43 | F33: 46 | G33: 19 | H33: =SUM(B33:G33) -> 262
A34: TOTAL | B34: =SUM(B30:B33) -> 103 | C34: =SUM(C30:C33) -> 114 | D34: =SUM(D30:D33) -> 93 | E34: =SUM(E30:E33) -> 81 | F34: =SUM(F30:F33) -> 102 | G34: =SUM(G30:G33) -> 36 | H34: =SUM(B34:G34) -> 529
A35: Bachman 2 | H35: =SUM(B35:G35) -> 0
A36: Mac | H36: =SUM(B36:G36) -> 0
B37: Mon | C37: Tues | D37: Wed | E37: Thur | F37: Fri | G37: Sat
A38: DATE | H38: Total
A39: Lisa | H39: =SUM(B39:G39) -> 0
A40: Bachman | H40: =SUM(B40:G40) -> 0
...

Sheet July Totals Madison 
B1: Mon | C1: Tues | D1: Wed | E1: Thur | F1: Fri | G1: Sat | H1: Sun
A2: DATE | B2: 45838 | C2: 45839 | D2: 45840 | E2: 45841 | F2: 45842 | G2: 45843 | H2: 45844 | I2: Totals
A3: Med | B3: 97 | C3: 103 | D3: 116 | E3: 100 | F3: 0 | G3: 0 | H3: 0 | I3: =SUM(B3:H3) -> 416
A4: Chiro | B4: 52 | C4: 61 | D4: 81 | E4: 45 | F4: 0 | G4: 17 | H4: 0 | I4: =SUM(B4:H4) -> 256
A5: Pod | B5: 10 | C5: 0 | D5: 14 | E5: 0 | F5: 0 | G5: 0 | H5: 0 | I5: =SUM(B5:H5) -> 24
A6: PT | B6: 6 | C6: 5 | D6: 8 | E6: 0 | F6: 0 | G6: 0 | H6: 0 | I6: =SUM(B6:H6) -> 19
A7: MA | B7: 3 | C7: 0 | D7: 0 | E7: 0 | F7: 0 | G7: 0 | H7: 0 | I7: =SUM(B7:H7) -> 3
A8: IV | B8: 1 | C8: 0 | D8: 2 | E8: 0 | F8: 0 | G8: 0 | H8: 0 | I8: =SUM(B8:H8) -> 3
A9: TOTAL | B9: =SUM(B3:B8) -> 169 | C9: =SUM(C3:C8) -> 169 | D9: =SUM(D3:D8) -> 221 | E9: =SUM(E3:E8) -> 145 | F9: =SUM(F3:F8) -> 0 | G9: =SUM(G3:G8) -> 17 | H9: =SUM(H3:H8) -> 0 | I9: =SUM(B9:H9) -> 721
A10: Covid Test | B10: 0 | C10: 0 | D10: 0 | E10: 0 | F10: 0 | G10: 0 | H10: 0 | I10: =SUM(B10:H10) -> 0
A11: Telehealth | B11: 0 | C11: 0 | D11: 0 | E11: 0 | F11: 0 | G11: 0 | H11: 0 | I11: =SUM(B11:H11) -> 0
B14: Mon | C14: Tues | D14: Wed | E14: Thur | F14: Fri | G14: Sat | H14: Sun
A15: DATE | B15: 45845 | C15: 45846 | D15: 45847 | E15: 45848 | F15: 45849 | G15: 45850 | H15: 45851 | I15: Totals
A16: Med | B16: 111 | C16: 99 | D16: 101 | E16: 62 | F16: 71 | G16: 44 | H16: 0 | I16: =SUM(B16:H16) -> 488
A17: Chiro | B17: 56 | C17: 53 | D17: 60 | E17: 35 | F17: 48 | G17: 15 | H17: 0 | I17: =SUM(B17:H17) -> 267
A18: Pod | B18: 13 | C18: 3 | D18: 11 | E18: 0 | F18: 16 | G18: 0 | H18: 0 | I18: =SUM(B18:H18) -> 43
A19: PT | B19: 9 | C19: 7 | D19: 5 | E19: 0 | F19: 9 | G19: 0 | H19: 0 | I19: =SUM(B19:H19) -> 30
A20: MA | B20: 2 | C20: 1 | D20: 1 | E20: 0 | F20: 0 | G20: 0 | H20: 0 | I20: =SUM(B20:H20) -> 4
A21: IV | B21: 0 | C21: 2 | D21: 0 | E21: 0 | F21: 3 | G21: 0 | H21: 0 | I21: =SUM(B21:H21) -> 5
A22: TOTAL | B22: =SUM(B16:B21) -> 191 | C22: =SUM(C16:C21) -> 165 | D22: =SUM(D16:D21) -> 178 | E22: =SUM(E16:E21) -> 97 | F22: =SUM(F16:F21) -> 147 | G22: =SUM(G16:G21) -> 59 | H22: =SUM(H16:H21) -> 0 | I22: =SUM(B22:H22) -> 837
A23: Covid Test | C23: 0 | D23: 0 | E23: 0 | F23: 0 | G23: 0 | H23: 0 | I23: =SUM(B23:H23) -> 0
A24: Telehealth | C24: 0 | D24: 0 | E24: 0 | F24: 0 | G24: 0 | H24: 0 | I24: =SUM(B24:H24) -> 0
B27: Mon | C27: Tues | D27: Wed | E27: Thur | F27: Fri | G27: Sat | H27: Sun
A28: DATE | B28: 45852 | C28: 45853 | D28: 45854 | E28: 45855 | F28: 45856 | G28: 45857 | H28: 45858 | I28: Totals
A29: Med | B29: 102 | C29: 102 | D29: 103 | E29: 109 | F29: 82 | G29: 32 | H29: 0 | I29: =SUM(B29:H29) -> 530
A30: Chiro | B30: 56 | C30: 55 | D30: 68 | E30: 44 | F30: 58 | G30: 15 | H30: 0 | I30: =SUM(B30:H30) -> 296
A31: Pod | B31: 15 | C31: 0 | D31: 0 | E31: 0 | F31: 15 | G31: 0 | H31: 0 | I31: =SUM(B31:H31) -> 30
A32: PT | B32: 6 | C32: 6 | D32: 7 | E32: 0 | F32: 7 | G32: 0 | H32: 0 | I32: =SUM(B32:H32) -> 26
A33: MA | B33: 1 | C33: 1 | D33: 0 | E33: 1 | F33: 1 | G33: 0 | H33: 0 | I33: =SUM(B33:H33) -> 4
A34: IV | B34: 3 | C34: 0 | D34: 1 | E34: 0 | F34: 1 | G34: 0 | H34: 0 | I34: =SUM(B34:H34) -> 5
A35: TOTAL | B35: =SUM(B29:B34) -> 183 | C35: =SUM(C29:C34) -> 164 | D35: =SUM(D29:D34) -> 179 | E35: =SUM(E29:E34) -> 154 | F35: =SUM(F29:F34) -> 164 | G35: =SUM(G29:G34) -> 47 | H35: =SUM(H29:H34) -> 0 | I35: =SUM(B35:H35) -> 891
A36: osman | B36: 9 | C36: 0 | D36: 0 | E36: 0 | F36: 0 | G36: 0 | H36: 0 | I36: =SUM(B36:H36) -> 9
A37: Shadani | B37: 0 | C37: 0 | D37: 0 | E37: 8 | F37: 0 | G37: 0 | H37: 0 | I37: =SUM(B37:H37) -> 8
B40: Mon | C40: Tues | D40: Wed | E40: Thur | F40: Fri | G40: Sat | H40: Sun
A41: DATE | B41: 45859 | C41: 45860 | D41: 45861 | E41: 45862 | F41: 45863 | G41: 45864 | H41: 45865 | I41: Totals
A42: Med | B42: 112 | C42: 94 | D42: 108 | E42: 97 | F42: 78 | G42: 38 | H42: 0 | I42: =SUM(B42:H42) -> 527
A43: Chiro | B43: 48 | C43: 47 | D43: 55 | E43: 40 | F43: 56 | G43: 29 | H43: 0 | I43: =SUM(B43:H43) -> 275
A44: Pod | B44: 21 | C44: 13 | D44: 6 | E44: 0 | F44: 9 | G44: 0 | H44: 0 | I44: =SUM(B44:H44) -> 49
A45: PT | B45: 6 | C45: 7 | D45: 6 | E45: 0 | F45: 8 | G45: 0 | H45: 0 | I45: =SUM(B45:H45) -> 27
A46: MA | B46: 3 | C46: 0 | D46: 3 | E46: 1 | F46: 0 | G46: 3 | H46: 0 | I46: =SUM(B46:H46) -> 10
...

Sheet July Provider Totals 
B1: Mon | C1: Tues | D1: Wed | E1: Thur | F1: Fri | G1: Sat
A2: DATE | B2: 45838 | C2: 45839 | D2: 45840 | E2: 45841 | F2: 45842 | G2: 45843 | H2: Total
A3: Lisa | B3: 20 | C3: 27 | D3: 28 | E3: 28 | F3: 0 | G3: 16 | H3: =SUM(B3:G3) -> 119
A4: Bachman | B4: 32 | C4: 27 | D4: 31 | E4: 21 | F4: 0 | G4: 0 | H4: =SUM(B4:G4) -> 111
A5: osman | B5: 9 | C5: 0 | D5: 0 | E5: 0 | F5: 0 | G5: 0 | H5: =SUM(B5:G5) -> 9
A6: Nurse | B6: 36 | C6: 49 | D6: 57 | E6: 51 | F6: 0 | G6: 22 | H6: =SUM(B6:G6) -> 215
A7: TOTAL | B7: =SUM(B3:B6) -> 97 | C7: =SUM(C3:C6) -> 103 | D7: =SUM(D3:D6) -> 116 | E7: =SUM(E3:E6) -> 100 | F7: =SUM(F3:F6) -> 0 | G7: =SUM(G3:G6) -> 38 | H7: =SUM(B7:G7) -> 454
A8: Bachman 2 | H8: =SUM(B8:G8) -> 0
A9: Mac | H9: =SUM(B9:G9) -> 0
B10: Mon | C10: Tues | D10: Wed | E10: Thur | F10: Fri | G10: Sat
A11: DATE | B11: 45845 | C11: 45846 | D11: 45847 | E11: 45848 | F11: 45849 | G11: 45850 | H11: Total
A12: Lisa | B12: 22 | C12: 19 | D12: 22 | E12: 0 | F12: 0 | G12: 0 | H12: =SUM(B12:G12) -> 63
A13: Bachman | B13: 29 | C13: 32 | D13: 31 | E13: 31 | F13: 35 | G13: 22 | H13: =SUM(B13:G13) -> 180
A14: osman | B14: 9 | C14: 0 | D14: 0 | E14: 0 | F14: 0 | G14: 0 | H14: =SUM(B14:G14) -> 9
A15: Nurse | B15: 51 | C15: 48 | D15: 48 | E15: 40 | F15: 25 | G15: 22 | H15: =SUM(B15:G15) -> 234
A16: TOTAL | B16: =SUM(B12:B15) -> 111 | C16: =SUM(C12:C15) -> 99 | D16: =SUM(D12:D15) -> 101 | E16: =SUM(E12:E15) -> 71 | F16: =SUM(F12:F15) -> 60 | G16: =SUM(G12:G15) -> 44 | H16: =SUM(B16:G16) -> 486
A17: Bachman 2 | H17: =SUM(B17:G17) -> 0
A18: Mac | H18: =SUM(B18:G18) -> 0
B19: Mon | C19: Tues | D19: Wed | E19: Thur | F19: Fri | G19: Sat
A20: DATE | B20: 45852 | C20: 45853 | D20: 45854 | E20: 45855 | F20: 45856 | G20: 45857 | H20: Total
A21: Lisa | B21: 17 | C21: 21 | D21: 22 | E21: 26 | F21: 21 | G21: 0 | H21: =SUM(B21:G21) -> 107
A22: Bachman | B22: 26 | C22: 25 | D22: 29 | E22: 31 | F22: 19 | G22: 12 | H22: =SUM(B22:G22) -> 142
A23: Laura | B23: 7 | C23: 5 | D23: 1 | E23: 3 | F23: 4 | G23: 0 | H23: =SUM(B23:G23) -> 20
A24: Nurse | B24: 44 | C24: 51 | D24: 48 | E24: 41 | F24: 38 | G24: 20 | H24: =SUM(B24:G24) -> 242
A25: TOTAL | B25: =SUM(B21:B24) -> 94 | C25: =SUM(C21:C24) -> 102 | D25: =SUM(D21:D24) -> 100 | E25: =SUM(E21:E24) -> 101 | F25: =SUM(F21:F24) -> 82 | G25: =SUM(G21:G24) -> 32 | H25: =SUM(B25:G25) -> 511
A26: Osman | B26: 8 | H26: =SUM(B26:G26) -> 8
A27: Leven | D27: 3 | H27: =SUM(B27:G27) -> 3
B28: Mon | C28: Tues | D28: Wed | E28: Thur | F28: Fri | G28: Sat
A29: DATE | B29: 45859 | C29: 45860 | D29: 45861 | E29: 45862 | F29: 45863 | G29: 45864 | H29: Total
A30: Lisa | B30: 25 | C30: 21 | D30: 18 | E30: 21 | F30: 14 | G30: 19 | H30: =SUM(B30:G30) -> 118
A31: Bachman | B31: 32 | C31: 19 | D31: 33 | E31: 28 | F31: 21 | G31: 0 | H31: =SUM(B31:G31) -> 133
A32: Laura | B32: 6 | C32: 6 | D32: 5 | E32: 6 | F32: 7 | G32: 0 | H32: =SUM(B32:G32) -> 30
A33: Nurse | B33: 40 | C33: 48 | D33: 52 | E33: 42 | F33: 36 | G33: 19 | H33: =SUM(B33:G33) -> 237
A34: TOTAL | B34: =SUM(B30:B33) -> 103 | C34: =SUM(C30:C33) -> 94 | D34: =SUM(D30:D33) -> 108 | E34: =SUM(E30:E33) -> 97 | F34: =SUM(F30:F33) -> 78 | G34: =SUM(G30:G33) -> 38 | H34: =SUM(B34:G34) -> 518
A35: osman | B35: 9 | H35: =SUM(B35:G35) -> 9
A36: Mac | H36: =SUM(B36:G36) -> 0
B37: Mon | C37: Tues | D37: Wed | E37: Thur | F37: Fri | G37: Sat
A38: DATE | B38: 45866 | C38: 45867 | D38: 45868 | E38: 45869 | F38: 45870 | G38: 45871 | H38: Total
A39: Lisa | B39: 16 | C39: 17 | D39: 21 | E39: 15 | F39: 19 | G39: 0 | H39: =SUM(B39:G39) -> 88
A40: Bachman | B40: 25 | C40: 26 | D40: 28 | E40: 19 | F40: 22 | G40: 15 | H40: =SUM(B40:G40) -> 135
...

Sheet AugustTotals Madison
B1: Mon | C1: Tues | D1: Wed | E1: Thur | F1: Fri | G1: Sat | H1: Sun
A2: DATE | B2: 45873 | C2: 45874 | D2: 45875 | E2: 45876 | F2: 45877 | G2: 45878 | H2: 45879 | I2: Totals
A3: Med | B3: 122 | C3: 105 | D3: 111 | E3: 97 | F3: 88 | G3: 36 | H3: 0 | I3: =SUM(B3:H3) -> 559
A4: Chiro | B4: 68 | C4: 53 | D4: 70 | E4: 47 | F4: 51 | G4: 14 | H4: 5 | I4: =SUM(B4:H4) -> 308
A5: Pod | B5: 9 | C5: 10 | D5: 6 | E5: 2 | F5: 10 | G5: 0 | H5: 0 | I5: =SUM(B5:H5) -> 37
A6: PT | B6: 5 | C6: 6 | D6: 7 | E6: 0 | F6: 10 | G6: 0 | H6: 0 | I6: =SUM(B6:H6) -> 28
A7: MA | B7: 1 | C7: 3 | D7: 1 | E7: 0 | F7: 0 | G7: 0 | H7: 0 | I7: =SUM(B7:H7) -> 5
A8: IV | B8: 1 | C8: 0 | D8: 1 | E8: 1 | F8: 4 | G8: 0 | H8: 0 | I8: =SUM(B8:H8) -> 7
A9: TOTAL | B9: =SUM(B3:B8) -> 206 | C9: =SUM(C3:C8) -> 177 | D9: =SUM(D3:D8) -> 196 | E9: =SUM(E3:E8) -> 147 | F9: =SUM(F3:F8) -> 163 | G9: =SUM(G3:G8) -> 50 | H9: =SUM(H3:H8) -> 5 | I9: =SUM(B9:H9) -> 944
A10: acu | B10: 3 | C10: 3 | D10: 4 | E10: 0 | F10: 0 | G10: 0 | H10: 0 | I10: =SUM(B10:H10) -> 10
A11: osman | B11: 14 | C11: 0 | D11: 0 | E11: 0 | F11: 0 | G11: 0 | H11: 0 | I11: =SUM(B11:H11) -> 14
B14: Mon | C14: Tues | D14: Wed | E14: Thur | F14: Fri | G14: Sat | H14: Sun
A15: DATE | B15: 45880 | C15: 45881 | D15: 45882 | E15: 45883 | F15: 45884 | G15: 45885 | H15: 45886 | I15: Totals
A16: Med | B16: 98 | C16: 95 | D16: 98 | E16: 104 | F16: 93 | G16: 39 | H16: 0 | I16: =SUM(B16:H16) -> 527
A17: Chiro | B17: 66 | C17: 54 | D17: 60 | E17: 40 | F17: 54 | G17: 17 | H17: 6 | I17: =SUM(B17:H17) -> 297
A18: Pod | B18: 18 | C18: 10 | D18: 8 | E18: 0 | F18: 14 | G18: 2 | H18: 0 | I18: =SUM(B18:H18) -> 52
A19: PT | B19: 0 | C19: 0 | D19: 0 | E19: 0 | F19: 0 | G19: 0 | H19: 0 | I19: =SUM(B19:H19) -> 0
A20: Acu | B20: 6 | C20: 10 | D20: 6 | E20: 0 | F20: 0 | G20: 0 | H20: 0 | I20: =SUM(B20:H20) -> 22
A21: IV and MA | B21: 6 | C21: 5 | D21: 2 | E21: 3 | F21: 4 | G21: 0 | H21: 0 | I21: =SUM(B21:H21) -> 20
A22: TOTAL | B22: =SUM(B16:B21) -> 194 | C22: =SUM(C16:C21) -> 174 | D22: =SUM(D16:D21) -> 174 | E22: =SUM(E16:E21) -> 147 | F22: =SUM(F16:F21) -> 165 | G22: =SUM(G16:G21) -> 58 | H22: =SUM(H16:H21) -> 6 | I22: =SUM(B22:H22) -> 918
A23: Covid Test | C23: 0 | D23: 0 | E23: 0 | F23: 0 | G23: 0 | H23: 0 | I23: =SUM(B23:H23) -> 0
A24: Telehealth | C24: 0 | D24: 0 | E24: 0 | F24: 0 | G24: 0 | H24: 0 | I24: =SUM(B24:H24) -> 0
B27: Mon | C27: Tues | D27: Wed | E27: Thur | F27: Fri | G27: Sat | H27: Sun
A28: DATE | B28: 45887 | C28: 45888 | D28: 45889 | E28: 45890 | F28: 45891 | G28: 45892 | H28: 45893 | I28: Totals
A29: Med | B29: 101 | C29: 109 | D29: 124 | E29: 104 | F29: 93 | G29: 45 | H29: 0 | I29: =SUM(B29:H29) -> 576
A30: Chiro | B30: 59 | C30: 60 | D30: 78 | E30: 25 | F30: 51 | G30: 20 | H30: 0 | I30: =SUM(B30:H30) -> 293
A31: Pod | B31: 17 | C31: 11 | D31: 10 | E31: 0 | F31: 0 | G31: 0 | H31: 0 | I31: =SUM(B31:H31) -> 38
A32: PT | B32: 0 | C32: 0 | D32: 0 | E32: 0 | F32: 0 | G32: 0 | H32: 0 | I32: =SUM(B32:H32) -> 0
A33: ACU | B33: 5 | C33: 9 | D33: 7 | E33: 0 | F33: 0 | G33: 0 | H33: 0 | I33: =SUM(B33:H33) -> 21
A34: IV & MA | B34: 2 | C34: 3 | D34: 4 | E34: 1 | F34: 2 | G34: 2 | H34: 0 | I34: =SUM(B34:H34) -> 14
A35: TOTAL | B35: =SUM(B29:B34) -> 184 | C35: =SUM(C29:C34) -> 192 | D35: =SUM(D29:D34) -> 223 | E35: =SUM(E29:E34) -> 130 | F35: =SUM(F29:F34) -> 146 | G35: =SUM(G29:G34) -> 67 | H35: =SUM(H29:H34) -> 0 | I35: =SUM(B35:H35) -> 942
A36: Covid Test | B36: 0 | C36: 0 | D36: 0 | E36: 0 | F36: 0 | G36: 0 | H36: 0 | I36: =SUM(B36:H36) -> 0
A37: Telehealth | B37: 0 | C37: 0 | D37: 0 | E37: 0 | F37: 0 | G37: 0 | H37: 0 | I37: =SUM(B37:H37) -> 0
B40: Mon | C40: Tues | D40: Wed | E40: Thur | F40: Fri | G40: Sat | H40: Sun
A41: DATE | B41: 45894 | C41: 45895 | D41: 45896 | E41: 45897 | F41: 45898 | G41: 45899 | H41: 45900 | I41: Totals
A42: Med | B42: 114 | C42: 101 | D42: 109 | E42: 84 | F42: 89 | G42: 44 | H42: 0 | I42: =SUM(B42:H42) -> 541
A43: Chiro | B43: 65 | C43: 55 | D43: 63 | E43: 44 | F43: 55 | G43: 26 | H43: 3 | I43: =SUM(B43:H43) -> 311
A44: Pod | B44: 18 | C44: 12 | D44: 12 | E44: 2 | F44: 14 | G44: 0 | H44: 0 | I44: =SUM(B44:H44) -> 58
A45: PT | B45: 0 | C45: 0 | D45: 0 | E45: 0 | F45: 0 | G45: 0 | H45: 0 | I45: =SUM(B45:H45) -> 0
A46: ACU | B46: 0 | C46: 8 | D46: 9 | E46: 1 | F46: 0 | G46: 0 | H46: 0 | I46: o
...

Sheet August Provider Totals 
B1: Mon | C1: Tues | D1: Wed | E1: Thur | F1: Fri | G1: Sat
A2: DATE | B2: 45873 | C2: 45874 | D2: 45875 | E2: 45876 | F2: 45877 | G2: 45878 | H2: Total
A3: Lisa | B3: 22 | C3: 21 | D3: 26 | E3: 24 | F3: 17 | G3: 16 | H3: =SUM(B3:G3) -> 126
